Workbook
Name partID: [1]parts!$A:$A
Name partLabel: [1]parts!$B:$B

Sheet maps
A1: IndexNum | B1: Martin Complete | C1: Complete | D1: PHA4GE_table | E1: sourceClass | F1: sourceSlot | G1: sourceValue | H1: targetClass | I1: wide? | J1: targetSlot | K1: targetValue | L1: notes2 | M1: customData | N1: notes | O1: Martin notes
A2: 1 | C2: =IF(AND(G2="NA",H2<>"wide_value"),TRUE,"") -> TRUE | D2: AMR detection information | E2: pha4ge | F2: AMR analysis report filename | G2: NA | H2: measures | J2: notes | K2: {{AMR analysis report filename}} | N2: Add to the measure row of an AMR target in the notes field. | O2: What are AMR measures?
A3: 2 | C3: =IF(AND(G3="NA",H3<>"wide_value"),TRUE,"") -> TRUE | D3: AMR detection information | E3: pha4ge | F3: AMR analysis software name | G3: NA | H3: {=IF(COUNTIF(wide_measures!D:D,INDIRECT("maps!F$"&ROW()))>0,"measures",IF(COUNTIF(wide_protocolSteps!C:C,INDIRECT("maps!F$"&ROW()))>0,"protocolSteps",IF(COUNTIF(wide_repositories!C:C,INDIRECT("maps!F$"&ROW()))>0,"repositories",IF(COUNTIF(wide_protocols!C:C,INDIRECT("maps!F$"&ROW()))>0,"protocols",""))))} -> protocolSteps | I3: wide_value | N3: link to AMR measures? Idk if there are any. | O3: What are AMR measures?
A4: 3 | B4: TRUE | C4: =IF(AND(G4="NA",H4<>"wide_value"),TRUE,"") -> TRUE | D4: AMR detection information | E4: pha4ge | F4: AMR analysis software version | G4: NA | H4: protocolSteps | J4: stepVer | K4: {{AMR analysis software version}} | N4: link to AMR analysis software name - this is a tentative mapping. | O4: What are AMR measures?
A5: 4 | C5: =IF(AND(G5="NA",H5<>"wide_value"),TRUE,"") -> TRUE | D5: AMR detection information | E5: pha4ge | F5: AMR reference database name | G5: NA | H5: accessions | J5: dataHost | K5: {{AMR reference database name}} | N5: link to AMR measures? Idk if there are any. | O5: What are AMR measures? No accessions table
A6: 5 | C6: =IF(AND(G6="NA",H6<>"wide_value"),TRUE,"") -> TRUE | D6: AMR detection information | E6: pha4ge | F6: AMR reference database version | G6: NA | H6: accessions | J6: hostVersion | K6: {{AMR reference database version}} | N6: link to AMR reference database name - this is a tentative mapping. | O6: What are AMR measures? No accessions table
A7: 6 | C7: =IF(AND(G7="NA",H7<>"wide_value"),TRUE,"") -> TRUE | D7: Bioinformatics and QC metrics | E7: pha4ge | F7: bioinformatics protocol | G7: NA | H7: protocols | J7: summ (OR reflink?) | K7: {{bioinformatics protocol}} | N7: link to other bioinformatics pieces from the PHA4GE bioinformatics table? | O7: What value to use for targetSlot?
A8: 7 | B8: TRUE | C8: =IF(AND(G8="NA",H8<>"wide_value"),TRUE,"") -> TRUE | D8: Bioinformatics and QC metrics | E8: pha4ge | F8: breadth of coverage value | G8: NA | H8: {=IF(COUNTIF(wide_measures!D:D,INDIRECT("maps!F$"&ROW()))>0,"measures",IF(COUNTIF(wide_protocolSteps!C:C,INDIRECT("maps!F$"&ROW()))>0,"protocolSteps",IF(COUNTIF(wide_repositories!C:C,INDIRECT("maps!F$"&ROW()))>0,"repositories",IF(COUNTIF(wide_protocols!C:C,INDIRECT("maps!F$"&ROW()))>0,"protocols",""))))} -> measures | I8: wide_value | N8: May need to link with separately stored units? | O8: See notes
A9: 8 | B9: TRUE | C9: =IF(AND(G9="NA",H9<>"wide_value"),TRUE,"") -> TRUE | D9: Bioinformatics and QC metrics | E9: pha4ge | F9: consensus genome length | G9: NA | H9: {=IF(COUNTIF(wide_measures!D:D,INDIRECT("maps!F$"&ROW()))>0,"measures",IF(COUNTIF(wide_protocolSteps!C:C,INDIRECT("maps!F$"&ROW()))>0,"protocolSteps",IF(COUNTIF(wide_repositories!C:C,INDIRECT("maps!F$"&ROW()))>0,"repositories",IF(COUNTIF(wide_protocols!C:C,INDIRECT("maps!F$"&ROW()))>0,"protocols",""))))} -> measures | I9: wide_value
A10: 9 | B10: TRUE | C10: =IF(AND(G10="NA",H10<>"wide_value"),TRUE,"") -> TRUE | D10: Bioinformatics and QC metrics | E10: pha4ge | F10: consensus sequence software name | G10: NA | H10: {=IF(COUNTIF(wide_measures!D:D,INDIRECT("maps!F$"&ROW()))>0,"measures",IF(COUNTIF(wide_protocolSteps!C:C,INDIRECT("maps!F$"&ROW()))>0,"protocolSteps",IF(COUNTIF(wide_repositories!C:C,INDIRECT("maps!F$"&ROW()))>0,"repositories",IF(COUNTIF(wide_protocols!C:C,INDIRECT("maps!F$"&ROW()))>0,"protocols",""))))} -> protocolSteps | I10: wide_value | N10: link to sequencing measures | O10: See notes
A11: 10 | B11: TRUE | C11: =IF(AND(G11="NA",H11<>"wide_value"),TRUE,"") -> TRUE | D11: Bioinformatics and QC metrics | E11: pha4ge | F11: consensus sequence software version | G11: NA | H11: protocolSteps | J11: stepVer | K11: {{consensus sequence software version}} | N11: link to consensus sequence software name - this is a tentative mapping.
A12: 11 | B12: TRUE | C12: =IF(AND(G12="NA",H12<>"wide_value"),TRUE,"") -> TRUE | D12: Bioinformatics and QC metrics | E12: pha4ge | F12: deduplication method | G12: NA | H12: {=IF(COUNTIF(wide_measures!D:D,INDIRECT("maps!F$"&ROW()))>0,"measures",IF(COUNTIF(wide_protocolSteps!C:C,INDIRECT("maps!F$"&ROW()))>0,"protocolSteps",IF(COUNTIF(wide_repositories!C:C,INDIRECT("maps!F$"&ROW()))>0,"repositories",IF(COUNTIF(wide_protocols!C:C,INDIRECT("maps!F$"&ROW()))>0,"protocols",""))))} -> protocolSteps | I12: wide_value | N12: link to sequencing measures - may need to figure out a standard way to string these tegother under a protocolID via relationships | O12: See notes
A13: 12 | B13: TRUE | C13: =IF(AND(G13="NA",H13<>"wide_value"),TRUE,"") -> TRUE | D13: Bioinformatics and QC metrics | E13: pha4ge | F13: dehosting method | G13: NA | H13: {=IF(COUNTIF(wide_measures!D:D,INDIRECT("maps!F$"&ROW()))>0,"measures",IF(COUNTIF(wide_protocolSteps!C:C,INDIRECT("maps!F$"&ROW()))>0,"protocolSteps",IF(COUNTIF(wide_repositories!C:C,INDIRECT("maps!F$"&ROW()))>0,"repositories",IF(COUNTIF(wide_protocols!C:C,INDIRECT("maps!F$"&ROW()))>0,"protocols",""))))} -> protocolSteps | I13: wide_value | N13: link to sequencing measures - may need to figure out a standard way to string these tegother under a protocolID via relationships | O13: See notes
A14: 13 | B14: TRUE | C14: =IF(AND(G14="NA",H14<>"wide_value"),TRUE,"") -> TRUE | D14: Bioinformatics and QC metrics | E14: pha4ge | F14: depth of coverage threshold | G14: NA | H14: {=IF(COUNTIF(wide_measures!D:D,INDIRECT("maps!F$"&ROW()))>0,"measures",IF(COUNTIF(wide_protocolSteps!C:C,INDIRECT("maps!F$"&ROW()))>0,"protocolSteps",IF(COUNTIF(wide_repositories!C:C,INDIRECT("maps!F$"&ROW()))>0,"repositories",IF(COUNTIF(wide_protocols!C:C,INDIRECT("maps!F$"&ROW()))>0,"protocols",""))))} -> measures | I14: wide_value
A15: 14 | B15: TRUE | C15: =IF(AND(G15="NA",H15<>"wide_value"),TRUE,"") -> TRUE | D15: Bioinformatics and QC metrics | E15: pha4ge | F15: depth of coverage value | G15: NA | H15: {=IF(COUNTIF(wide_measures!D:D,INDIRECT("maps!F$"&ROW()))>0,"measures",IF(COUNTIF(wide_protocolSteps!C:C,INDIRECT("maps!F$"&ROW()))>0,"protocolSteps",IF(COUNTIF(wide_repositories!C:C,INDIRECT("maps!F$"&ROW()))>0,"repositories",IF(COUNTIF(wide_protocols!C:C,INDIRECT("maps!F$"&ROW()))>0,"protocols",""))))} -> measures | I15: wide_value | N15: May need to link with separately stored units? | O15: See notes
A16: 15 | B16: TRUE | C16: =IF(AND(G16="NA",H16<>"wide_value"),TRUE,"") -> TRUE | D16: Bioinformatics and QC metrics | E16: pha4ge | F16: genome completeness | G16: NA | H16: {=IF(COUNTIF(wide_measures!D:D,INDIRECT("maps!F$"&ROW()))>0,"measures",IF(COUNTIF(wide_protocolSteps!C:C,INDIRECT("maps!F$"&ROW()))>0,"protocolSteps",IF(COUNTIF(wide_repositories!C:C,INDIRECT("maps!F$"&ROW()))>0,"repositories",IF(COUNTIF(wide_protocols!C:C,INDIRECT("maps!F$"&ROW()))>0,"protocols",""))))} -> measures | I16: wide_value
A17: 16 | B17: TRUE | C17: =IF(AND(G17="NA",H17<>"wide_value"),TRUE,"") -> TRUE | D17: Bioinformatics and QC metrics | E17: pha4ge | F17: minimum post-trimming read length | G17: NA | H17: {=IF(COUNTIF(wide_measures!D:D,INDIRECT("maps!F$"&ROW()))>0,"measures",IF(COUNTIF(wide_protocolSteps!C:C,INDIRECT("maps!F$"&ROW()))>0,"protocolSteps",IF(COUNTIF(wide_repositories!C:C,INDIRECT("maps!F$"&ROW()))>0,"repositories",IF(COUNTIF(wide_protocols!C:C,INDIRECT("maps!F$"&ROW()))>0,"protocols",""))))} -> measures | I17: wide_value
A18: 17 | B18: TRUE | C18: =IF(AND(G18="NA",H18<>"wide_value"),TRUE,"") -> TRUE | D18: Bioinformatics and QC metrics | E18: pha4ge | F18: N50 | G18: NA | H18: {=IF(COUNTIF(wide_measures!D:D,INDIRECT("maps!F$"&ROW()))>0,"measures",IF(COUNTIF(wide_protocolSteps!C:C,INDIRECT("maps!F$"&ROW()))>0,"protocolSteps",IF(COUNTIF(wide_repositories!C:C,INDIRECT("maps!F$"&ROW()))>0,"repositories",IF(COUNTIF(wide_protocols!C:C,INDIRECT("maps!F$"&ROW()))>0,"protocols",""))))} -> measures | I18: wide_value
A19: 18 | B19: TRUE | C19: =IF(AND(G19="NA",H19<>"wide_value"),TRUE,"") -> TRUE | D19: Bioinformatics and QC metrics | E19: pha4ge | F19: Ns per 100 kbp | G19: NA | H19: {=IF(COUNTIF(wide_measures!D:D,INDIRECT("maps!F$"&ROW()))>0,"measures",IF(COUNTIF(wide_protocolSteps!C:C,INDIRECT("maps!F$"&ROW()))>0,"protocolSteps",IF(COUNTIF(wide_repositories!C:C,INDIRECT("maps!F$"&ROW()))>0,"repositories",IF(COUNTIF(wide_protocols!C:C,INDIRECT("maps!F$"&ROW()))>0,"protocols",""))))} -> measures | I19: wide_value
A20: 19 | B20: TRUE | C20: =IF(AND(G20="NA",H20<>"wide_value"),TRUE,"") -> TRUE | D20: Bioinformatics and QC metrics | E20: pha4ge | F20: number of base pairs sequenced | G20: NA | H20: {=IF(COUNTIF(wide_measures!D:D,INDIRECT("maps!F$"&ROW()))>0,"measures",IF(COUNTIF(wide_protocolSteps!C:C,INDIRECT("maps!F$"&ROW()))>0,"protocolSteps",IF(COUNTIF(wide_repositories!C:C,INDIRECT("maps!F$"&ROW()))>0,"repositories",IF(COUNTIF(wide_protocols!C:C,INDIRECT("maps!F$"&ROW()))>0,"protocols",""))))} -> measures | I20: wide_value
A21: 20 | B21: TRUE | C21: =IF(AND(G21="NA",H21<>"wide_value"),TRUE,"") -> TRUE | D21: Bioinformatics and QC metrics | E21: pha4ge | F21: number of contigs | G21: NA | H21: {=IF(COUNTIF(wide_measures!D:D,INDIRECT("maps!F$"&ROW()))>0,"measures",IF(COUNTIF(wide_protocolSteps!C:C,INDIRECT("maps!F$"&ROW()))>0,"protocolSteps",IF(COUNTIF(wide_repositories!C:C,INDIRECT("maps!F$"&ROW()))>0,"repositories",IF(COUNTIF(wide_protocols!C:C,INDIRECT("maps!F$"&ROW()))>0,"protocols",""))))} -> measures | I21: wide_value
A22: 21 | B22: TRUE | C22: =IF(AND(G22="NA",H22<>"wide_value"),TRUE,"") -> TRUE | D22: Bioinformatics and QC metrics | E22: pha4ge | F22: number of total reads | G22: NA | H22: {=IF(COUNTIF(wide_measures!D:D,INDIRECT("maps!F$"&ROW()))>0,"measures",IF(COUNTIF(wide_protocolSteps!C:C,INDIRECT("maps!F$"&ROW()))>0,"protocolSteps",IF(COUNTIF(wide_repositories!C:C,INDIRECT("maps!F$"&ROW()))>0,"repositories",IF(COUNTIF(wide_protocols!C:C,INDIRECT("maps!F$"&ROW()))>0,"protocols",""))))} -> measures | I22: wide_value
A23: 22 | B23: TRUE | C23: =IF(AND(G23="NA",H23<>"wide_value"),TRUE,"") -> TRUE | D23: Bioinformatics and QC metrics | E23: pha4ge | F23: number of unique reads | G23: NA | H23: {=IF(COUNTIF(wide_measures!D:D,INDIRECT("maps!F$"&ROW()))>0,"measures",IF(COUNTIF(wide_protocolSteps!C:C,INDIRECT("maps!F$"&ROW()))>0,"protocolSteps",IF(COUNTIF(wide_repositories!C:C,INDIRECT("maps!F$"&ROW()))>0,"repositories",IF(COUNTIF(wide_protocols!C:C,INDIRECT("maps!F$"&ROW()))>0,"protocols",""))))} -> measures | I23: wide_value
A24: 23 | B24: TRUE | C24: =IF(AND(G24="NA",H24<>"wide_value"),TRUE,"") -> TRUE | D24: Bioinformatics and QC metrics | E24: pha4ge | F24: percent Ns across total genome length | G24: NA | H24: {=IF(COUNTIF(wide_measures!D:D,INDIRECT("maps!F$"&ROW()))>0,"measures",IF(COUNTIF(wide_protocolSteps!C:C,INDIRECT("maps!F$"&ROW()))>0,"protocolSteps",IF(COUNTIF(wide_repositories!C:C,INDIRECT("maps!F$"&ROW()))>0,"repositories",IF(COUNTIF(wide_protocols!C:C,INDIRECT("maps!F$"&ROW()))>0,"protocols",""))))} -> measures | I24: wide_value
A25: 24 | B25: TRUE | C25: =IF(AND(G25="NA",H25<>"wide_value"),TRUE,"") -> TRUE | D25: Bioinformatics and QC metrics | E25: pha4ge | F25: percent read contamination | G25: NA | H25: {=IF(COUNTIF(wide_measures!D:D,INDIRECT("maps!F$"&ROW()))>0,"measures",IF(COUNTIF(wide_protocolSteps!C:C,INDIRECT("maps!F$"&ROW()))>0,"protocolSteps",IF(COUNTIF(wide_repositories!C:C,INDIRECT("maps!F$"&ROW()))>0,"repositories",IF(COUNTIF(wide_protocols!C:C,INDIRECT("maps!F$"&ROW()))>0,"protocols",""))))} -> measures | I25: wide_value
A26: 25 | C26: =IF(AND(G26="NA",H26<>"wide_value"),TRUE,"") -> TRUE | D26: Bioinformatics and QC metrics | E26: pha4ge | F26: quality control details | G26: NA | H26: qualityReports | J26: notes | K26: {{quality control details}} | N26: Need linkage to the measureRepID for the sequencing, generate qulaityIDs. | O26: See notes
A27: 26 | C27: =IF(AND(G27="NA",H27<>"wide_value"),TRUE,"") | D27: Bioinformatics and QC metrics | E27: pha4ge | F27: quality control determination | G27: no quality control issues identified | H27: qualityReports | J27: qualityFlag | K27: noConcern | N27: Need linkage to the measureRepID for the sequencing, generate qulaityIDs. | O27: See notes
A28: 27 | C28: =IF(AND(G28="NA",H28<>"wide_value"),TRUE,"") | D28: Bioinformatics and QC metrics | E28: pha4ge | F28: quality control determination | G28: sequence passed quality control | H28: measures | J28: reportable | K28: TRUE | N28: report with sequencing measure | O28: See notes
A29: 28 | C29: =IF(AND(G29="NA",H29<>"wide_value"),TRUE,"") | D29: Bioinformatics and QC metrics | E29: pha4ge | F29: quality control determination | G29: sequence failed quality control | H29: measures | J29: reportable | K29: FALSE | N29: report with sequencing measure | O29: See notes
A30: 29 | C30: =IF(AND(G30="NA",H30<>"wide_value"),TRUE,"") | D30: Bioinformatics and QC metrics | E30: pha4ge | F30: quality control determination | G30: minor quality control issues identified | H30: measures | J30: reportable | K30: TRUE | N30: Generate a quality report with the the quality flag "qf1" to accompany this report, and then report both with the sequencing measure | O30: See notes
A31: 30 | C31: =IF(AND(G31="NA",H31<>"wide_value"),TRUE,"") | D31: Bioinformatics and QC metrics | E31: pha4ge | F31: quality control determination | G31: sequence flagged for potential quality control issues | H31: measures | J31: reportable | K31: TRUE | N31: Generate a quality report with the the quality flag "qf1" to accompany this report, and then report both with the sequencing measure | O31: See notes
A32: 31 | C32: =IF(AND(G32="NA",H32<>"wide_value"),TRUE,"") | D32: Bioinformatics and QC metrics | E32: pha4ge | F32: quality control determination | G32: quality control not performed | H32: measures | J32: reportable | K32: nr | N32: report with sequencing measure | O32: See notes
A33: 32 | C33: =IF(AND(G33="NA",H33<>"wide_value"),TRUE,"") | D33: Bioinformatics and QC metrics | E33: pha4ge | F33: quality control issues | G33: low quality sequence | H33: qualityReports | J33: qualityFlag | K33: lowQualSeq | N33: Need linkage to the measureRepID for the sequencing, generate qulaityIDs. | O33: See notes
A34: 33 | C34: =IF(AND(G34="NA",H34<>"wide_value"),TRUE,"") | D34: Bioinformatics and QC metrics | E34: pha4ge | F34: quality control issues | G34: sequence contaminated | H34: qualityReports | J34: qualityFlag | K34: seqContam | N34: Need linkage to the measureRepID for the sequencing, generate qulaityIDs. | O34: See notes
A35: 34 | C35: =IF(AND(G35="NA",H35<>"wide_value"),TRUE,"") | D35: Bioinformatics and QC metrics | E35: pha4ge | F35: quality control issues | G35: low average genome coverage | H35: qualityReports | J35: qualityFlag | K35: lAGC | N35: Need linkage to the measureRepID for the sequencing, generate qulaityIDs. | O35: See notes
A36: 35 | C36: =IF(AND(G36="NA",H36<>"wide_value"),TRUE,"") | D36: Bioinformatics and QC metrics | E36: pha4ge | F36: quality control issues | G36: low percent genome captured | H36: qualityReports | J36: qualityFlag | K36: lPGC | N36: Need linkage to the measureRepID for the sequencing, generate qulaityIDs. | O36: See notes
A37: 36 | C37: =IF(AND(G37="NA",H37<>"wide_value"),TRUE,"") | D37: Bioinformatics and QC metrics | E37: pha4ge | F37: quality control issues | G37: read lengths shorter than expected | H37: qualityReports | J37: qualityFlag | K37: shortRead | N37: Need linkage to the measureRepID for the sequencing, generate qulaityIDs. | O37: See notes
A38: 37 | C38: =IF(AND(G38="NA",H38<>"wide_value"),TRUE,"") | D38: Bioinformatics and QC metrics | E38: pha4ge | F38: quality control issues | G38: sequence amplification artifacts | H38: qualityReports | J38: qualityFlag | K38: ampliArtifact | N38: Need linkage to the measureRepID for the sequencing, generate qulaityIDs. | O38: See notes
A39: 38 | C39: =IF(AND(G39="NA",H39<>"wide_value"),TRUE,"") | D39: Bioinformatics and QC metrics | E39: pha4ge | F39: quality control issues | G39: low signal to noise ratio | H39: qualityReports | J39: qualityFlag | K39: lowSNRatio | N39: Need linkage to the measureRepID for the sequencing, generate qulaityIDs. | O39: See notes
A40: 39 | C40: =IF(AND(G40="NA",H40<>"wide_value"),TRUE,"") | D40: Bioinformatics and QC metrics | E40: pha4ge | F40: quality control issues | G40: low coverage of characteristic mutations | H40: qualityReports | J40: qualityFlag | K40: lowCovMut | N40: Need linkage to the measureRepID for the sequencing, generate qulaityIDs. | O40: See notes
...

Sheet maps_OTHER
A1: IndexNum | B1: Martin Complete | C1: Complete | D1: PHA4GE_table | E1: sourceClass | F1: sourceSlot | G1: sourceValue | H1: targetClass | I1: wide? | J1: targetSlot | K1: targetValue | L1: notes2 | M1: customData | N1: notes | O1: Martin notes
A2: 216 | B2: TRUE | D2: Environmental conditions and measurements | E2: pha4ge | F2: water catchment human population measurement method | I2: wide_value
A3: 229 | B3: TRUE | D3: NA | E3: pha4ge | F3: null values | G3: Not Applicable | H3: NA | J3: NA | K3: NA | N3: both values map to the NA value as it's used in ODM.
A4: 230 | B4: TRUE | D4: NA | E4: pha4ge | F4: null values | G4: Not Collected | H4: NA | J4: NA | K4: NA | N4: both values map to the NA value as it's used in ODM.
A5: 231 | B5: TRUE | D5: NA | E5: pha4ge | F5: null values | G5: Not Provided | H5: NA | J5: NA | K5: undisc
A6: 232 | B6: TRUE | D6: NA | E6: pha4ge | F6: null values | G6: Missing | H6: NA | J6: NA | K6: nr
A7: 233 | B7: TRUE | D7: NA | E7: pha4ge | F7: null values | G7: Restricted Access | H7: NA | J7: NA | K7: restrict
A8: 676 | D8: Sample collection and processing | E8: pha4ge | F8: specimen processing | G8: Pooling specimens | H8: [caputured under {{database identifiers - pooled sample ID}}] | N8: [caputured under {{database identifiers - pooled sample ID}}] | O8: Not sure about notes

Sheet maps_sites
A1: IndexNum | B1: Martin Complete | C1: Complete | D1: PHA4GE_table | E1: sourceClass | F1: sourceSlot | G1: sourceValue | H1: targetClass | I1: wide? | J1: targetSlot | K1: targetValue | L1: notes2 | M1: customData | N1: notes | O1: Martin notes
A2: 61 | B2: TRUE | C2: TRUE | D2: Database identifiers | E2: pha4ge | F2: sampling site ID | G2: NA | H2: sites | J2: siteID | K2: {{sampling site ID}}
A3: 287 | B3: TRUE | D3: Sample collection and processing | E3: pha4ge | F3: environmental site | G3: Correctional facility | H3: sites | J3: sampleShed | K3: sampleShed:corFcil | O3: Maps to different slot based on sourceValue of enumeration
A4: 288 | B4: TRUE | D4: Sample collection and processing | E4: pha4ge | F4: environmental site | G4: Healthcare facility | H4: sites | J4: sampleShed | K4: sampleShed:hcf | O4: Maps to different slot based on sourceValue of enumeration
A5: 289 | B5: TRUE | D5: Sample collection and processing | E5: pha4ge | F5: environmental site | G5: Hospital | H5: sites | J5: sampleShed | K5: sampleShed:hosptl | O5: Maps to different slot based on sourceValue of enumeration
A6: 290 | B6: TRUE | D6: Sample collection and processing | E6: pha4ge | F6: environmental site | G6: Clinic | H6: sites | J6: sampleShed | K6: sampleShed:clinic | O6: Maps to different slot based on sourceValue of enumeration
A7: 291 | B7: TRUE | D7: Sample collection and processing | E7: pha4ge | F7: environmental site | G7: Educational facility | H7: sites | J7: sampleShed | K7: sampleShed:edFac | O7: Maps to different slot based on sourceValue of enumeration
A8: 292 | B8: TRUE | D8: Sample collection and processing | E8: pha4ge | F8: environmental site | G8: Daycare facility | H8: sites | J8: sampleShed | K8: sampleShed:cdc | O8: Maps to different slot based on sourceValue of enumeration
A9: 293 | B9: TRUE | D9: Sample collection and processing | E9: pha4ge | F9: environmental site | G9: School | H9: sites | J9: sampleShed | K9: sampleShed:school | O9: Maps to different slot based on sourceValue of enumeration
A10: 294 | B10: TRUE | D10: Sample collection and processing | E10: pha4ge | F10: environmental site | G10: College or university | H10: sites | J10: sampleShed | K10: sampleShed:uCampus | O10: Maps to different slot based on sourceValue of enumeration
A11: 295 | B11: TRUE | D11: Sample collection and processing | E11: pha4ge | F11: environmental site | G11: Residential building | H11: sites | J11: sampleShed | K11: sampleShed:orb | O11: Maps to different slot based on sourceValue of enumeration
A12: 296 | B12: TRUE | D12: Sample collection and processing | E12: pha4ge | F12: environmental site | G12: Homeless shelter | H12: sites | J12: sampleShed | K12: sampleShed:sss | O12: Maps to different slot based on sourceValue of enumeration
A13: 297 | B13: TRUE | D13: Sample collection and processing | E13: pha4ge | F13: environmental site | G13: Long-term care facility | H13: sites | J13: sampleShed | K13: sampleShed:ltcfAl | O13: Maps to different slot based on sourceValue of enumeration
A14: 298 | B14: TRUE | D14: Sample collection and processing | E14: pha4ge | F14: environmental site | G14: Transport hub | H14: sites | J14: sampleShed | K14: sampleShed:tHub | O14: Maps to different slot based on sourceValue of enumeration
... A38: 322 | B38: TRUE | D38: Sample collection and processing | E38: pha4ge | F38: environmental site | G38: Wastewater treatment plant | H38: sites | J38: siteType | K38: siteType:wwtp | O38: Maps to different slot based on sourceValue of enumeration
A39: 333 | B39: TRUE | C39: TRUE | D39: Sample collection and processing | E39: pha4ge | F39: geo loc latitude | G39: NA | H39: sites | J39: geoLat | K39: {{geo loc latitude}}
A40: 334 | B40: TRUE | C40: TRUE | D40: Sample collection and processing | E40: pha4ge | F40: geo loc longitude | G40: NA | H40: sites | J40: geoLong | K40: {{geo loc longitude}}
A41: 336 | B41: TRUE | C41: TRUE | D41: Sample collection and processing | E41: pha4ge | F41: geo_loc name (site) | G41: NA | H41: sites | J41: name | K41: {{geo_loc name (site)}}
A42: 680 | D42: Sample collection and processing | E42: pha4ge | F42: wastewater system type | G42: Combined sewer system | H42: sites | J42: siteType | K42: wwtpMuC | N42: Need to cross reference with the {{environmental site}} field | O42: "environmental site" maps to same slot (siteType+sampleShed)
A43: 681 | D43: Sample collection and processing | E43: pha4ge | F43: wastewater system type | G43: Sanitary sewer system | H43: sites | J43: siteType | K43: wwtpMuS | N43: Need to cross reference with the {{environmental site}} field | O43: "environmental site" maps to same slot (siteType+sampleShed)
A44: 682 | D44: Sample collection and processing | E44: pha4ge | F44: wastewater system type | G44: Sewer (drain) | H44: sites | J44: siteType | K44: drain | N44: Need to cross reference with the {{environmental site}} field | O44: "environmental site" maps to same slot (siteType+sampleShed)
A45: 683 | D45: Sample collection and processing | E45: pha4ge | F45: wastewater system type | G45: Waste stabilization pond | H45: sites | J45: siteType | K45: stabPnd | N45: Need to cross reference with the {{environmental site}} field | O45: "environmental site" maps to same slot (siteType+sampleShed)
A46: 684 | D46: Sample collection and processing | E46: pha4ge | F46: wastewater system type | G46: Latrine | H46: sites | J46: siteType | K46: latrine | N46: Need to cross reference with the {{environmental site}} field | O46: "environmental site" maps to same slot (siteType+sampleShed)
A47: 685 | D47: Sample collection and processing | E47: pha4ge | F47: wastewater system type | G47: Septic tank | H47: sites | J47: siteType | K47: septTnk | N47: Need to cross reference with the {{environmental site}} field | O47: "environmental site" maps to same slot (siteType+sampleShed)
A48: 686 | D48: Sample collection and processing | E48: pha4ge | F48: wastewater system type | G48: Cesspit | H48: sites | J48: siteType | K48: cesspit | N48: Need to cross reference with the {{environmental site}} field | O48: "environmental site" maps to same slot (siteType+sampleShed)
A49: 687 | D49: Sample collection and processing | E49: pha4ge | F49: wastewater system type | G49: Composting toilet | H49: sites | J49: siteType | K49: compToi | N49: Need to cross reference with the {{environmental site}} field | O49: "environmental site" maps to same slot (siteType+sampleShed)

Sheet maps_samples
A1: IndexNum | B1: Martin Complete | C1: Complete | D1: PHA4GE_table | E1: sourceClass | F1: sourceSlot | G1: sourceValue | H1: targetClass | I1: wide? | J1: targetSlot | K1: targetValue | L1: targetExpr | M1: notes2 | N1: customData | O1: notes | P1: Martin notes
A2: 59 | B2: TRUE | C2: FALSE | D2: Database identifiers | E2: pha4ge | F2: pooled sample ID | G2: NA | H2: samples | J2: sampleID | K2: {{pooled sample ID}} | O2: also populate 'pooled' with 'TRUE'; need to be linked to original sample ID through the relationships table with a "child" relationship (this pooled sample is child). | P2: See notes. Should be in wide table? Which one is the original sampleID?
A3: 60 | B3: TRUE | C3: FALSE | D3: Database identifiers | E3: pha4ge | F3: sampling event ID | G3: NA | H3: samples | J3: sampleID | K3: {{sampling event ID}} | O3: also populate 'repType' with 'sampleEvent'; need to be linked to original sample ID through the relationships table with a "child" relationship, where the original sample is the "child" of this sample. | P3: See notes. Should be in wide table? Which one is the original sampleID?
A4: 63 | B4: TRUE | C4: FALSE | D4: Database identifiers | E4: pha4ge | F4: specimen collector sample ID | G4: NA | H4: samples | J4: sampleID | K4: {{specimen collector sample ID}} | P4: Should be wide?
A5: 64 | B5: TRUE | C5: FALSE | D5: Database identifiers | E5: pha4ge | F5: specimen collector subsample ID | G5: NA | H5: samples | J5: sampleID | K5: {{specimen collector subsample ID}} | O5: also populate 'repType' with 'subSamp'; need to be linked to original sample ID through the relationships table with a "child" relationship (this subsample is child). | P5: See notes. Should be in wide table? Which one is the original sampleID?
B6: TRUE | C6: FALSE | D6: Sample collection and processing | E6: pha4ge | F6: collection device | J6: collType | L6: case((collection_device != "", collection_device), (True, collection_method))
A7: 249 | B7: TRUE | C7: FALSE | D7: Sample collection and processing | E7: pha4ge | F7: collection device | G7: Grab sampler | H7: samples | J7: collType | K7: grb | O7: Collection device and collection method are collapsed into a single field, generally, within the ODM. So when both are being mapped to collType, the {{collection Device}} value should supercede {{collection method}}, but here the collection method should match with a value of "Grab Sampling".
A8: 250 | B8: TRUE | C8: FALSE | D8: Sample collection and processing | E8: pha4ge | F8: collection device | G8: Core sampling device | H8: samples | J8: collType | K8: core | O8: Collection device and collection method are collapsed into a single field, generally, within the ODM. So when both are being mapped to collType, the {{collection Device}} value should supercede {{collection method}}, but here the collection method should match with a value of "Grab Sampling".
A9: 251 | B9: TRUE | C9: FALSE | D9: Sample collection and processing | E9: pha4ge | F9: collection device | G9: Vacuum sludge sampling device | H9: samples | J9: collType | K9: vac | O9: Collection device and collection method are collapsed into a single field, generally, within the ODM. So when both are being mapped to collType, the {{collection Device}} value should supercede {{collection method}}, but here the collection method should match with a value of "Grab Sampling".
A10: 252 | B10: TRUE | C10: FALSE | D10: Sample collection and processing | E10: pha4ge | F10: collection device | G10: Cone-shaped sampling device | H10: samples | J10: collType | K10: one | O10: Collection device and collection method are collapsed into a single field, generally, within the ODM. So when both are being mapped to collType, the {{collection Device}} value should supercede {{collection method}}, but here the collection method should match with a value of "Grab Sampling".
A11: 253 | B11: TRUE | C11: FALSE | D11: Sample collection and processing | E11: pha4ge | F11: collection device | G11: Horizontal grab sampling device | H11: samples | J11: collType | K11: horGrb | O11: Collection device and collection method are collapsed into a single field, generally, within the ODM. So when both are being mapped to collType, the {{collection Device}} value should supercede {{collection method}}, but here the collection method should match with a value of "Grab Sampling".
A12: 254 | B12: TRUE | C12: FALSE | D12: Sample collection and processing | E12: pha4ge | F12: collection device | G12: Vertical grab sampling device | H12: samples | J12: collType | K12: vertGrb | O12: Collection device and collection method are collapsed into a single field, generally, within the ODM. So when both are being mapped to collType, the {{collection Device}} value should supercede {{collection method}}, but here the collection method should match with a value of "Grab Sampling".
A13: 255 | B13: TRUE | C13: FALSE | D13: Sample collection and processing | E13: pha4ge | F13: collection device | G13: Composite sampler | H13: samples | J13: collType | K13: comp | O13: Collection device and collection method are collapsed into a single field, generally, within the ODM. So when both are being mapped to collType, the {{collection Device}} value should supercede {{collection method}}, but here the collection method should match with a value of "Composite Sampling".
A14: 256 | B14: TRUE | C14: FALSE | D14: Sample collection and processing | E14: pha4ge | F14: collection device | G14: Passive (trap) sampler | H14: samples | J14: collType | K14: trap | O14: Collection device and collection method are collapsed into a single field, generally, within the ODM. So when both are being mapped to collType, the {{collection Device}} value should supercede {{collection method}}, but here the collection method should match with a value of "Passive Composite Sampling".
A15: 257 | B15: TRUE | C15: FALSE | D15: Sample collection and processing | E15: pha4ge | F15: collection device | G15: Moore swab | H15: samples | J15: collType | K15: moorSw | O15: Collection device and collection method are collapsed into a single field, generally, within the ODM. So when both are being mapped to collType, the {{collection Device}} value should supercede {{collection method}}, but here the collection method should match with a value of "Passive Composite Sampling".
A16: 258 | B16: TRUE | C16: FALSE | D16: Sample collection and processing | E16: pha4ge | F16: collection device | G16: Automatic composite sampler | H16: samples | J16: collType | K16: autoComp | O16: Collection device and collection method are collapsed into a single field, generally, within the ODM. So when both are being mapped to collType, the {{collection Device}} value should supercede {{collection method}}, but here the collection method should match with a value of "Automatic Composite Sampling".
A17: 259 | B17: TRUE | C17: FALSE | D17: Sample collection and processing | E17: pha4ge | F17: collection device | G17: Automatic flow-proportional sampler | H17: samples | J17: collType | K17: flowPr | O17: Collection device and collection method are collapsed into a single field, generally, within the ODM. So when both are being mapped to collType, the {{collection Device}} value should supercede {{collection method}}, but here the collection method should match with a value of "Automatic Composite Sampling".
A18: 260 | B18: TRUE | C18: FALSE | D18: Sample collection and processing | E18: pha4ge | F18: collection device | G18: Automatic sequential sampler | H18: samples | J18: collType | K18: autoSeq | O18: Collection device and collection method are collapsed into a single field, generally, within the ODM. So when both are being mapped to collType, the {{collection Device}} value should supercede {{collection method}}, but here the collection method should match with a value of "Automatic Composite Sampling".
... A23: 265 | B23: TRUE | C23: FALSE | D23: Sample collection and processing | E23: pha4ge | F23: collection method | G23: Manual composite sampling | H23: samples | J23: collType | K23: manComp | O23: This mapping pre-supposes that the collection device field is blank.
A25: 267 | B25: TRUE | C25: FALSE | D25: Sample collection and processing | E25: pha4ge | F25: environmental material | G25: surface water | H25: samples | J25: saMaterial | K25: nww | O25: match to sampleID entry row | P25: Which sampleID row?
A26: 268 | B26: TRUE | C26: FALSE | D26: Sample collection and processing | E26: pha4ge | F26: environmental material | G26: wastewater | H26: samples | J26: saMaterial | K26: rawWW | O26: match to sampleID entry row
A27: 269 | B27: TRUE | C27: FALSE | D27: Sample collection and processing | E27: pha4ge | F27: environmental material | G27: Wastewater sediment | H27: samples | J27: saMaterial | K27: swrSed | O27: match to sampleID entry row
A28: 270 | B28: TRUE | C28: FALSE | D28: Sample collection and processing | E28: pha4ge | F28: environmental material | G28: Sludge | H28: samples | J28: saMaterial | K28: sludgeNS | O28: match to sampleID entry row
A29: 271 | B29: TRUE | C29: FALSE | D29: Sample collection and processing | E29: pha4ge | F29: environmental material | G29: Primary sludge | H29: samples | J29: saMaterial | K29: pSludge | O29: match to sampleID entry row
A30: 272 | B30: TRUE | C30: FALSE | D30: Sample collection and processing | E30: pha4ge | F30: environmental material | G30: Secondary sludge | H30: samples | J30: saMaterial | K30: sSludge | O30: match to sampleID entry row
A31: 273 | B31: TRUE | C31: FALSE | D31: Sample collection and processing | E31: pha4ge | F31: environmental material | G31: Wastewater effluent | H31: samples | J31: saMaterial | K31: effluNS | O31: match to sampleID entry row
A32: 274 | B32: TRUE | C32: FALSE | D32: Sample collection and processing | E32: pha4ge | F32: environmental material | G32: Primary wastwater effluent | H32: samples | J32: saMaterial | K32: pEfflu | O32: match to sampleID entry row
A33: 275 | B33: TRUE | C33: FALSE | D33: Sample collection and processing | E33: pha4ge | F33: environmental material | G33: Secondary wastwater effluent | H33: samples | J33: saMaterial | K33: sEfflu | O33: match to sampleID entry row
A35: 325 | B35: TRUE | C35: FALSE | D35: Sample collection and processing | E35: pha4ge | F35: experimental specimen role type | G35: Positive experimental control | H35: samples | J35: repType | K35: posCon
A36: 326 | B36: TRUE | C36: FALSE | D36: Sample collection and processing | E36: pha4ge | F36: experimental specimen role type | G36: Negative experimental control | H36: samples | J36: repType | K36: negCon
A37: 327 | B37: TRUE | C37: FALSE | D37: Sample collection and processing | E37: pha4ge | F37: experimental specimen role type | G37: Technical replicate | H37: samples | J37: repType | K37: techRep
A38: 328 | B38: TRUE | C38: FALSE | D38: Sample collection and processing | E38: pha4ge | F38: experimental specimen role type | G38: Biological replicate | H38: samples | J38: repType | K38: bioRep
A39: 622 | B39: TRUE | C39: FALSE | D39: Sample collection and processing | E39: pha4ge | F39: purpose of sampling | G39: Wastewater treatment efficiency assessment | H39: samples | J39: purposeID | K39: wwtpAssess | O39: match to sampleID entry row; plus add compartment = "wat" | P39: Add compartment = "wat" and match to the sampleID row
A40: 623 | B40: TRUE | C40: FALSE | D40: Sample collection and processing | E40: pha4ge | F40: purpose of sampling | G40: Wastewater chemical surveillance | H40: samples | J40: purposeID | K40: chemSurv | O40: match to sampleID entry row; plus add compartment = "wat" | P40: Add compartment = "wat" and match to the sampleID row
A41: 624 | B41: TRUE | C41: FALSE | D41: Sample collection and processing | E41: pha4ge | F41: purpose of sampling | G41: Wastewater drug surveillance | H41: samples | J41: purposeID | K41: drugSurv | O41: match to sampleID entry row; plus add compartment = "wat" | P41: Add compartment = "wat" and match to the sampleID row
A42: 625 | B42: TRUE | C42: FALSE | D42: Sample collection and processing | E42: pha4ge | F42: purpose of sampling | G42: Wastewater pathogen surveillance | H42: samples | J42: purposeID | K42: regular | O42: match to sampleID entry row; plus add compartment = "wat" | P42: Add compartment = "wat" and match to the sampleID row
A43: 626 | B43: TRUE | C43: FALSE | D43: Sample collection and processing | E43: pha4ge | F43: purpose of sampling | G43: Research | H43: samples | J43: purposeID | K43: researchPurp | O43: match to sampleID entry row | P43: Add compartment = "wat" and match to the sampleID row
A44: 627 | B44: TRUE | C44: FALSE | D44: Sample collection and processing | E44: pha4ge | F44: purpose of sampling | G44: Environmental survey (profiling) | H44: samples | J44: purposeID | K44: profil | O44: match to sampleID entry row | P44: Add compartment = "wat" and match to the sampleID row
A45: 628 | B45: TRUE | C45: FALSE | D45: Sample collection and processing | E45: pha4ge | F45: purpose of sampling | G45: Protocol testing | H45: samples | J45: purposeID | K45: testing | O45: match to sampleID entry row | P45: Add compartment = "wat" and match to the sampleID row
A46: 629 | B46: TRUE | C46: FALSE | D46: Sample collection and processing | E46: pha4ge | F46: sample collected by | G46: NA | H46: samples | J46: organizationID | K46: {{sample collected by}} | O46: Ultimately for each row in the pha4ge data, there may be up to 4 rows generated in the "contacts" ODM table. 1) Sample collector, 2) sequenced by, 3) sequence submitted by, and 4) isolated by. Complementary contacts metadata need to be grouped together under these ubrellas, but still be separate rows. Furthermore, the "sequenced by/sequence submitted by/isolated by contactIDs should be linked to the measures table, while the sample collector contactID should link to the samples table.
...

Sheet wide_samples
A1: Complete | B1: wideSourceClass | C1: wideSourceSlot | D1: wideSourceValue | E1: wideTargetClass | F1: wideOtherSlots | G1: sampleID_value | H1: wideNotes
A2: TRUE | B2: pha4ge | C2: pooled sample ID | E2: samples | F2: { "pooled_value": TRUE } | G2: {{pooled sample ID}} | H2: also populate 'pooled' with 'TRUE'; need to be linked to original sample ID through the relationships table with a "child" relationship (this pooled sample is child).
A3: TRUE | B3: pha4ge | C3: sampling event ID | E3: samples | F3: { "repType_value": "sampleEvent" } | G3: {{sampling event ID}} | H3: also populate 'repType' with 'sampleEvent'; need to be linked to original sample ID through the relationships table with a "child" relationship, where the original sample is the "child" of this sample.
A4: TRUE | B4: pha4ge | C4: specimen collector sample ID | E4: samples | F4: { "collType_expr": "case((collection_device != "", collection_device), (True, collection_method))", "saMaterial_value": "{{environmental material}}", "repType_value": "{{experimental specimen role type}}", "purposeID_value": "{{purpose of sampling}}", "organizationID_value": "{{sample collected by}}", "collDT_expr": "sample_collection_date + '/!/' + sample_collection_start_time", "collDTStart_expr": "sample_collection_start_time", "collDTEnd_expr": "sample_collection_end_date + '/!/' + sample_collection_end_time", "collPer_expr": "_value = src.sample_collection_time_duration_value _unit = src.sample_collection_time_duration_unit if _unit == 'Second': target = _value / 60 / 60 elif _unit == 'Minute': target = _value / 60 elif _unit == 'Hour': target = _value elif _unit == 'Day': target = _value * 24 elif _unit == 'Week': target = _value * 24 * 7 elif _unit == 'Month': target = _value * 24 * 7 * 30 elif _unit == 'Year': target = _value * 24 * 7 * 365 else: target = '' raise ValueError('Unrecognized value for sample_collection_time_duration_unit: ' + _unit)", "recDate_value": "{{sample received date}}", } | G4: {{specimen collector sample ID}}
A5: TRUE | B5: pha4ge | C5: specimen collector subsample ID | E5: samples | F5: { "repType_value": "subSamp" } | G5: {{specimen collector subsample ID}} | H5: also populate 'repType' with 'subSamp'; need to be linked to original sample ID through the relationships table with a "child" relationship (this subsample is child).
A6: TRUE | B6: pha4ge | C6: alternative isolate ID | E6: samples | G6: {{alternative isolate ID}}
A7: TRUE | B7: pha4ge | C7: isolate ID | E7: samples | F7: { "recDate_value": "{{isolate received date}}" } | G7: {{isolate ID}}
A8: TRUE | B8: pha4ge | C8: progeny isolate ID | E8: samples | G8: {{progeny isolate ID}}

Sheet enums_samples
A1: IndexNum | B1: Complete | C1: PHA4GE_table | D1: sourceClass | E1: sourceSlot | F1: sourceValue | G1: targetClass | H1: targetSlot | I1: targetValue | J1: exprValue | K1: customData | L1: notes | M1: Martin Notes
A2: 249 | B2: =IF(OR(F2="NA",G2="wide_value"),"",TRUE) -> TRUE | C2: Sample collection and processing | D2: pha4ge | E2: collection device | F2: Grab sampler | G2: samples | H2: collType | I2: grb | L2: Collection device and collection method are collapsed into a single field, generally, within the ODM. So when both are being mapped to collType, the {{collection Device}} value should supercede {{collection method}}, but here the collection method should match with a value of "Grab Sampling".
A3: 250 | B3: =IF(OR(F3="NA",G3="wide_value"),"",TRUE) -> TRUE | C3: Sample collection and processing | D3: pha4ge | E3: collection device | F3: Core sampling device | G3: samples | H3: collType | I3: core | L3: Collection device and collection method are collapsed into a single field, generally, within the ODM. So when both are being mapped to collType, the {{collection Device}} value should supercede {{collection method}}, but here the collection method should match with a value of "Grab Sampling".
A4: 251 | B4: =IF(OR(F4="NA",G4="wide_value"),"",TRUE) -> TRUE | C4: Sample collection and processing | D4: pha4ge | E4: collection device | F4: Vacuum sludge sampling device | G4: samples | H4: collType | I4: vac | L4: Collection device and collection method are collapsed into a single field, generally, within the ODM. So when both are being mapped to collType, the {{collection Device}} value should supercede {{collection method}}, but here the collection method should match with a value of "Grab Sampling".
A5: 252 | B5: =IF(OR(F5="NA",G5="wide_value"),"",TRUE) -> TRUE | C5: Sample collection and processing | D5: pha4ge | E5: collection device | F5: Cone-shaped sampling device | G5: samples | H5: collType | I5: one | L5: Collection device and collection method are collapsed into a single field, generally, within the ODM. So when both are being mapped to collType, the {{collection Device}} value should supercede {{collection method}}, but here the collection method should match with a value of "Grab Sampling".
A6: 253 | B6: =IF(OR(F6="NA",G6="wide_value"),"",TRUE) -> TRUE | C6: Sample collection and processing | D6: pha4ge | E6: collection device | F6: Horizontal grab sampling device | G6: samples | H6: collType | I6: horGrb | L6: Collection device and collection method are collapsed into a single field, generally, within the ODM. So when both are being mapped to collType, the {{collection Device}} value should supercede {{collection method}}, but here the collection method should match with a value of "Grab Sampling".
A7: 254 | B7: =IF(OR(F7="NA",G7="wide_value"),"",TRUE) -> TRUE | C7: Sample collection and processing | D7: pha4ge | E7: collection device | F7: Vertical grab sampling device | G7: samples | H7: collType | I7: vertGrb | L7: Collection device and collection method are collapsed into a single field, generally, within the ODM. So when both are being mapped to collType, the {{collection Device}} value should supercede {{collection method}}, but here the collection method should match with a value of "Grab Sampling".
A8: 255 | B8: =IF(OR(F8="NA",G8="wide_value"),"",TRUE) -> TRUE | C8: Sample collection and processing | D8: pha4ge | E8: collection device | F8: Composite sampler | G8: samples | H8: collType | I8: comp | L8: Collection device and collection method are collapsed into a single field, generally, within the ODM. So when both are being mapped to collType, the {{collection Device}} value should supercede {{collection method}}, but here the collection method should match with a value of "Composite Sampling".
A9: 256 | B9: =IF(OR(F9="NA",G9="wide_value"),"",TRUE) -> TRUE | C9: Sample collection and processing | D9: pha4ge | E9: collection device | F9: Passive (trap) sampler | G9: samples | H9: collType | I9: trap | L9: Collection device and collection method are collapsed into a single field, generally, within the ODM. So when both are being mapped to collType, the {{collection Device}} value should supercede {{collection method}}, but here the collection method should match with a value of "Passive Composite Sampling".
A10: 257 | B10: =IF(OR(F10="NA",G10="wide_value"),"",TRUE) -> TRUE | C10: Sample collection and processing | D10: pha4ge | E10: collection device | F10: Moore swab | G10: samples | H10: collType | I10: moorSw | L10: Collection device and collection method are collapsed into a single field, generally, within the ODM. So when both are being mapped to collType, the {{collection Device}} value should supercede {{collection method}}, but here the collection method should match with a value of "Passive Composite Sampling".
A11: 258 | B11: =IF(OR(F11="NA",G11="wide_value"),"",TRUE) -> TRUE | C11: Sample collection and processing | D11: pha4ge | E11: collection device | F11: Automatic composite sampler | G11: samples | H11: collType | I11: autoComp | L11: Collection device and collection method are collapsed into a single field, generally, within the ODM. So when both are being mapped to collType, the {{collection Device}} value should supercede {{collection method}}, but here the collection method should match with a value of "Automatic Composite Sampling".
A12: 259 | B12: =IF(OR(F12="NA",G12="wide_value"),"",TRUE) -> TRUE | C12: Sample collection and processing | D12: pha4ge | E12: collection device | F12: Automatic flow-proportional sampler | G12: samples | H12: collType | I12: flowPr | L12: Collection device and collection method are collapsed into a single field, generally, within the ODM. So when both are being mapped to collType, the {{collection Device}} value should supercede {{collection method}}, but here the collection method should match with a value of "Automatic Composite Sampling".
A13: 260 | B13: =IF(OR(F13="NA",G13="wide_value"),"",TRUE) -> TRUE | C13: Sample collection and processing | D13: pha4ge | E13: collection device | F13: Automatic sequential sampler | G13: samples | H13: collType | I13: autoSeq | L13: Collection device and collection method are collapsed into a single field, generally, within the ODM. So when both are being mapped to collType, the {{collection Device}} value should supercede {{collection method}}, but here the collection method should match with a value of "Automatic Composite Sampling".
... A29: 275 | B29: =IF(OR(F29="NA",G29="wide_value"),"",TRUE) -> TRUE | C29: Sample collection and processing | D29: pha4ge | E29: environmental material | F29: Secondary wastwater effluent | G29: samples | H29: saMaterial | I29: sEfflu | L29: match to sampleID entry row
A31: 325 | B31: =IF(OR(F31="NA",G31="wide_value"),"",TRUE) -> TRUE | C31: Sample collection and processing | D31: pha4ge | E31: experimental specimen role type | F31: Positive experimental control | G31: samples | H31: repType | I31: posCon
A32: 326 | B32: =IF(OR(F32="NA",G32="wide_value"),"",TRUE) -> TRUE | C32: Sample collection and processing | D32: pha4ge | E32: experimental specimen role type | F32: Negative experimental control | G32: samples | H32: repType | I32: negCon
A33: 327 | B33: =IF(OR(F33="NA",G33="wide_value"),"",TRUE) -> TRUE | C33: Sample collection and processing | D33: pha4ge | E33: experimental specimen role type | F33: Technical replicate | G33: samples | H33: repType | I33: techRep
A34: 328 | B34: =IF(OR(F34="NA",G34="wide_value"),"",TRUE) -> TRUE | C34: Sample collection and processing | D34: pha4ge | E34: experimental specimen role type | F34: Biological replicate | G34: samples | H34: repType | I34: bioRep
A36: 622 | B36: =IF(OR(F36="NA",G36="wide_value"),"",TRUE) -> TRUE | C36: Sample collection and processing | D36: pha4ge | E36: purpose of sampling | F36: Wastewater treatment efficiency assessment | G36: samples | H36: purposeID | I36: wwtpAssess | L36: match to sampleID entry row; plus add compartment = "wat"
A37: 623 | B37: =IF(OR(F37="NA",G37="wide_value"),"",TRUE) -> TRUE | C37: Sample collection and processing | D37: pha4ge | E37: purpose of sampling | F37: Wastewater chemical surveillance | G37: samples | H37: purposeID | I37: chemSurv | L37: match to sampleID entry row; plus add compartment = "wat"
A38: 624 | B38: =IF(OR(F38="NA",G38="wide_value"),"",TRUE) -> TRUE | C38: Sample collection and processing | D38: pha4ge | E38: purpose of sampling | F38: Wastewater drug surveillance | G38: samples | H38: purposeID | I38: drugSurv | L38: match to sampleID entry row; plus add compartment = "wat"
A39: 625 | B39: =IF(OR(F39="NA",G39="wide_value"),"",TRUE) -> TRUE | C39: Sample collection and processing | D39: pha4ge | E39: purpose of sampling | F39: Wastewater pathogen surveillance | G39: samples | H39: purposeID | I39: regular | L39: match to sampleID entry row; plus add compartment = "wat"
A40: 626 | B40: =IF(OR(F40="NA",G40="wide_value"),"",TRUE) -> TRUE | C40: Sample collection and processing | D40: pha4ge | E40: purpose of sampling | F40: Research | G40: samples | H40: purposeID | I40: researchPurp | L40: match to sampleID entry row
A41: 627 | B41: =IF(OR(F41="NA",G41="wide_value"),"",TRUE) -> TRUE | C41: Sample collection and processing | D41: pha4ge | E41: purpose of sampling | F41: Environmental survey (profiling) | G41: samples | H41: purposeID | I41: profil | L41: match to sampleID entry row
A42: 628 | B42: =IF(OR(F42="NA",G42="wide_value"),"",TRUE) -> TRUE | C42: Sample collection and processing | D42: pha4ge | E42: purpose of sampling | F42: Protocol testing | G42: samples | H42: purposeID | I42: testing | L42: match to sampleID entry row

Sheet wide_sampleRelationships
A1: Complete | B1: wideSourceClass | C1: wideSourceSlot | D1: wideSourceValue | E1: wideTargetClass | F1: wideOtherSlots | G1: sampleRelationshipsID_value | H1: sampleIDSubject_value | I1: relationshipID_value | J1: sampleIDObject_value | K1: wideNotes
A2: TRUE | B2: pha4ge | C2: pooled sample ID | E2: sampleRelationships | H2: {{pooled sample ID}} | I2: child | J2: {{specimen collector sample ID}}
A3: TRUE | B3: pha4ge | C3: specimen collector sample ID | E3: sampleRelationships | H3: {{specimen collector sample ID}} | I3: child | J3: {{sampling event ID}}
A4: TRUE | B4: pha4ge | C4: specimen collector subsample ID | E4: sampleRelationships | H4: {{specimen collector subsample ID}} | I4: child | J4: {{specimen collector sample ID}}
A5: TRUE | B5: pha4ge | C5: alternative isolate ID | E5: sampleRelationships | H5: {{alternative isolate ID}} | I5: child | J5: {{specimen collector sample ID}} | K5: Check with Mathew if correct
A6: TRUE | B6: pha4ge | C6: isolate ID | E6: sampleRelationships | H6: {{isolate ID}} | I6: child | J6: {{specimen collector sample ID}} | K6: Check with Mathew if correct
A7: TRUE | B7: pha4ge | C7: isolate ID | E7: sampleRelationships | H7: {{isolate ID}} | I7: labDuplicate | J7: {{alternative isolate ID}} | K7: Check with Mathew if correct
A8: TRUE | B8: pha4ge | C8: progeny isolate ID | E8: sampleRelationships | H8: {{progeny isolate ID}} | I8: child | J8: {{specimen collector sample ID}} | K8: Check with Mathew if correct

Sheet maps_repositories
A1: IndexNum | B1: Martin Complete | C1: Complete | D1: PHA4GE_table | E1: sourceClass | F1: sourceSlot | G1: sourceValue | H1: targetClass | I1: wide? | J1: targetSlot | K1: targetValue | L1: notes2 | M1: customData | N1: notes | O1: Martin notes
A2: 48 | B2: TRUE | C2: FALSE | D2: Database identifiers | E2: pha4ge | F2: BioProject accession | G2: NA | H2: repositories | I2: wide_value
A3: 49 | B3: TRUE | C3: FALSE | D3: Database identifiers | E3: pha4ge | F3: BioSample accession | G3: NA | H3: repositories | I3: wide_value
A4: 50 | B4: TRUE | C4: FALSE | D4: Database identifiers | E4: pha4ge | F4: DDBJ accession | G4: NA | H4: repositories | I4: wide_value
A5: 51 | B5: TRUE | C5: FALSE | D5: Database identifiers | E5: pha4ge | F5: DRA accession | G5: NA | H5: repositories | I5: wide_value
A6: 52 | B6: TRUE | C6: FALSE | D6: Database identifiers | E6: pha4ge | F6: ENA accession | G6: NA | H6: repositories | I6: wide_value
A7: 53 | B7: TRUE | C7: FALSE | D7: Database identifiers | E7: pha4ge | F7: Enterobase accession | G7: NA | H7: repositories | I7: wide_value
A8: 54 | B8: TRUE | C8: FALSE | D8: Database identifiers | E8: pha4ge | F8: GenBank accession (versioned) | G8: NA | H8: repositories | I8: wide_value
A9: 55 | B9: TRUE | C9: FALSE | D9: Database identifiers | E9: pha4ge | F9: GISAID accession | G9: NA | H9: repositories | I9: wide_value
A10: 56 | B10: TRUE | C10: FALSE | D10: Database identifiers | E10: pha4ge | F10: GISAID virus name | G10: NA | H10: repositories | J10: notes | K10: {{GISAID virus name}} | N10: map to notes, match with GISAID entry
A11: 57 | B11: TRUE | C11: FALSE | D11: Database identifiers | E11: pha4ge | F11: GSA accession | G11: NA | H11: repositories | I11: wide_value
A12: 58 | B12: TRUE | C12: FALSE | D12: Database identifiers | E12: pha4ge | F12: metagenome-assembled genome (MAG) ID | G12: NA | H12: repositories | I12: wide_value
A13: 65 | B13: TRUE | C13: FALSE | D13: Database identifiers | E13: pha4ge | F13: SRA accession | G13: NA | H13: repositories | I13: wide_value

Sheet wide_repositories
A1: Complete | B1: wideSourceClass | C1: wideSourceSlot | D1: wideSourceValue | E1: wideTargetClass | F1: dataRepo_value | G1: wideOtherSlots | H1: value_value | I1: wideNotes
B2: pha4ge | C2: BioProject accession | E2: repositories | F2: insdc | H2: {{BioProject accession}}
B3: pha4ge | C3: BioSample accession | E3: repositories | F3: insdc | H3: {{BioSample accession}}
B4: pha4ge | C4: DDBJ accession | E4: repositories | F4: ddbj | H4: {{DDBJ accession}}
B5: pha4ge | C5: DRA accession | E5: repositories | F5: dra | H5: {{DRA accession}}
B6: pha4ge | C6: ENA accession | E6: repositories | F6: ena | H6: {{ENA accession}}
B7: pha4ge | C7: Enterobase accession | E7: repositories | F7: enterobase | H7: {{Enterobase accession}}
B8: pha4ge | C8: GenBank accession (versioned) | E8: repositories | F8: genBank | H8: {{GenBank accession (versioned)}}
B9: pha4ge | C9: GISAID accession | E9: repositories | F9: gisaid | G9: { "notes_value" : "{{GISAID virus name}}" } | H9: {{GISAID accession}}
B10: pha4ge | C10: GSA accession | E10: repositories | F10: gsa | H10: {{GSA accession}}
B11: pha4ge | C11: metagenome-assembled genome (MAG) ID | E11: repositories | F11: mag | H11: {{metagenome-assembled genome (MAG) ID}}
B12: pha4ge | C12: SRA accession | E12: repositories | F12: sra | H12: {{SRA accession }}

Sheet maps_qualityReports
A1: IndexNum | B1: Martin Complete | C1: Complete | D1: PHA4GE_table | E1: sourceClass | F1: sourceSlot | G1: sourceValue | H1: targetClass | I1: wide? | J1: targetSlot | K1: targetValue | L1: notes2 | M1: customData | N1: notes | O1: Martin notes
A2: 25 | C2: TRUE | D2: Bioinformatics and QC metrics | E2: pha4ge | F2: quality control details | G2: NA | H2: qualityReports | J2: notes | K2: {{quality control details}} | N2: Need linkage to the measureRepID for the sequencing, generate qulaityIDs. | O2: See notes
A3: 26 | D3: Bioinformatics and QC metrics | E3: pha4ge | F3: quality control determination | G3: no quality control issues identified | H3: qualityReports | J3: qualityFlag | K3: noConcern | N3: Need linkage to the measureRepID for the sequencing, generate qulaityIDs. | O3: See notes
A4: 32 | D4: Bioinformatics and QC metrics | E4: pha4ge | F4: quality control issues | G4: low quality sequence | H4: qualityReports | J4: qualityFlag | K4: lowQualSeq | N4: Need linkage to the measureRepID for the sequencing, generate qulaityIDs. | O4: See notes
A5: 33 | D5: Bioinformatics and QC metrics | E5: pha4ge | F5: quality control issues | G5: sequence contaminated | H5: qualityReports | J5: qualityFlag | K5: seqContam | N5: Need linkage to the measureRepID for the sequencing, generate qulaityIDs. | O5: See notes
A6: 34 | D6: Bioinformatics and QC metrics | E6: pha4ge | F6: quality control issues | G6: low average genome coverage | H6: qualityReports | J6: qualityFlag | K6: lAGC | N6: Need linkage to the measureRepID for the sequencing, generate qulaityIDs. | O6: See notes
A7: 35 | D7: Bioinformatics and QC metrics | E7: pha4ge | F7: quality control issues | G7: low percent genome captured | H7: qualityReports | J7: qualityFlag | K7: lPGC | N7: Need linkage to the measureRepID for the sequencing, generate qulaityIDs. | O7: See notes
A8: 36 | D8: Bioinformatics and QC metrics | E8: pha4ge | F8: quality control issues | G8: read lengths shorter than expected | H8: qualityReports | J8: qualityFlag | K8: shortRead | N8: Need linkage to the measureRepID for the sequencing, generate qulaityIDs. | O8: See notes
A9: 37 | D9: Bioinformatics and QC metrics | E9: pha4ge | F9: quality control issues | G9: sequence amplification artifacts | H9: qualityReports | J9: qualityFlag | K9: ampliArtifact | N9: Need linkage to the measureRepID for the sequencing, generate qulaityIDs. | O9: See notes
A10: 38 | D10: Bioinformatics and QC metrics | E10: pha4ge | F10: quality control issues | G10: low signal to noise ratio | H10: qualityReports | J10: qualityFlag | K10: lowSNRatio | N10: Need linkage to the measureRepID for the sequencing, generate qulaityIDs. | O10: See notes
A11: 39 | D11: Bioinformatics and QC metrics | E11: pha4ge | F11: quality control issues | G11: low coverage of characteristic mutations | H11: qualityReports | J11: qualityFlag | K11: lowCovMut | N11: Need linkage to the measureRepID for the sequencing, generate qulaityIDs. | O11: See notes

Sheet maps_protocolSteps
A1: IndexNum | B1: Martin Complete | C1: Complete | D1: PHA4GE_table | E1: sourceClass | F1: sourceSlot | G1: sourceValue | H1: targetClass | I1: wide? | J1: targetSlot | K1: targetValue | L1: notes2 | M1: customData | N1: notes | O1: Martin notes
A2: 2 | C2: TRUE | D2: AMR detection information | E2: pha4ge | F2: AMR analysis software name | G2: NA | H2: protocolSteps | I2: wide_value | N2: link to AMR measures? Idk if there are any. | O2: What are AMR measures?
A3: 3 | B3: TRUE | C3: TRUE | D3: AMR detection information | E3: pha4ge | F3: AMR analysis software version | G3: NA | H3: protocolSteps | J3: stepVer | K3: {{AMR analysis software version}} | N3: link to AMR analysis software name - this is a tentative mapping. | O3: What are AMR measures?
