Workbook
Name partID: [1]parts!$A:$A
Name partLabel: [1]parts!$B:$B

Sheet maps_OTHER
A1: IndexNum | B1: Martin Complete | C1: Complete | D1: PHA4GE_table | E1: sourceClass | F1: sourceSlot | G1: sourceValue | H1: targetClass | I1: wide? | J1: targetSlot | K1: targetValue | L1: notes2 | M1: customData | N1: notes | O1: Martin notes
A2: These are currently unused
A3: 216 | B3: TRUE | D3: Environmental conditions and measurements | E3: PHA4GE | F3: water catchment area human population measurement method | I3: wide_value
A4: 229 | B4: TRUE | D4: NA | E4: PHA4GE | F4: null values | G4: Not Applicable | H4: NA | J4: NA | K4: NA | N4: both values map to the NA value as it's used in ODM.
A5: 230 | B5: TRUE | D5: NA | E5: PHA4GE | F5: null values | G5: Not Collected | H5: NA | J5: NA | K5: NA | N5: both values map to the NA value as it's used in ODM.
A6: 231 | B6: TRUE | D6: NA | E6: PHA4GE | F6: null values | G6: Not Provided | H6: NA | J6: NA | K6: undisc
A7: 232 | B7: TRUE | D7: NA | E7: PHA4GE | F7: null values | G7: Missing | H7: NA | J7: NA | K7: nr
A8: 233 | B8: TRUE | D8: NA | E8: PHA4GE | F8: null values | G8: Restricted Access | H8: NA | J8: NA | K8: restrict
A9: 676 | D9: Sample collection and processing | E9: PHA4GE | F9: specimen processing | G9: Pooling specimens | H9: [caputured under {{database identifiers - pooled sample ID}}] | N9: [caputured under {{database identifiers - pooled sample ID}}] | O9: Not sure about notes

Sheet maps_sites
A1: IndexNum | B1: Martin Complete | C1: Complete | D1: PHA4GE_table | E1: PHA4GE Class | F1: sourceClass | G1: sourceSlot | H1: sourceValue | I1: targetClass | J1: wide? | K1: targetSlot | L1: targetValue | M1: notes2 | N1: customData | O1: notes | P1: Martin notes
A2: 61 | B2: TRUE | C2: TRUE | D2: Database identifiers | E2: =IF(G2<>"",VLOOKUP(G2,PHA4GEVars!$A$7:$B$241,2,FALSE),"") -> Database identifiers | F2: PHA4GE | G2: sampling site ID | I2: sites | K2: siteID | L2: {{sampling site ID}}
E3: =IF(G3<>"",VLOOKUP(G3,PHA4GEVars!$A$7:$B$241,2,FALSE),"")
A4: 287 | B4: TRUE | C4: TRUE | D4: Sample collection and processing | E4: =IF(G4<>"",VLOOKUP(G4,PHA4GEVars!$A$7:$B$241,2,FALSE),"") -> Sample collection and processing | F4: PHA4GE | G4: environmental site | H4: Correctional facility | I4: sites | K4: sampleShed | L4: sampleShed:corFcil | P4: In ID generator: Map to sampleShed if preceded by "sampleShed:", map to siteType if preceded by "siteType:". If siteType is already populated from "wastewater system type", then "wastewater system type" takes precedence
A5: 288 | B5: TRUE | C5: TRUE | D5: Sample collection and processing | E5: =IF(G5<>"",VLOOKUP(G5,PHA4GEVars!$A$7:$B$241,2,FALSE),"") -> Sample collection and processing | F5: PHA4GE | G5: environmental site | H5: Healthcare facility | I5: sites | K5: sampleShed | L5: sampleShed:hcf | P5: In ID generator: Map to sampleShed if preceded by "sampleShed:", map to siteType if preceded by "siteType:". If siteType is already populated from "wastewater system type", then "wastewater system type" takes precedence
A6: 289 | B6: TRUE | C6: TRUE | D6: Sample collection and processing | E6: =IF(G6<>"",VLOOKUP(G6,PHA4GEVars!$A$7:$B$241,2,FALSE),"") -> Sample collection and processing | F6: PHA4GE | G6: environmental site | H6: Hospital | I6: sites | K6: sampleShed | L6: sampleShed:hosptl | P6: In ID generator: Map to sampleShed if preceded by "sampleShed:", map to siteType if preceded by "siteType:". If siteType is already populated from "wastewater system type", then "wastewater system type" takes precedence
A7: 290 | B7: TRUE | C7: TRUE | D7: Sample collection and processing | E7: =IF(G7<>"",VLOOKUP(G7,PHA4GEVars!$A$7:$B$241,2,FALSE),"") -> Sample collection and processing | F7: PHA4GE | G7: environmental site | H7: Clinic | I7: sites | K7: sampleShed | L7: sampleShed:clinic | P7: In ID generator: Map to sampleShed if preceded by "sampleShed:", map to siteType if preceded by "siteType:". If siteType is already populated from "wastewater system type", then "wastewater system type" takes precedence
A8: 291 | B8: TRUE | C8: TRUE | D8: Sample collection and processing | E8: =IF(G8<>"",VLOOKUP(G8,PHA4GEVars!$A$7:$B$241,2,FALSE),"") -> Sample collection and processing | F8: PHA4GE | G8: environmental site | H8: Educational facility | I8: sites | K8: sampleShed | L8: sampleShed:edFac | P8: In ID generator: Map to sampleShed if preceded by "sampleShed:", map to siteType if preceded by "siteType:". If siteType is already populated from "wastewater system type", then "wastewater system type" takes precedence
A9: 292 | B9: TRUE | C9: TRUE | D9: Sample collection and processing | E9: =IF(G9<>"",VLOOKUP(G9,PHA4GEVars!$A$7:$B$241,2,FALSE),"") -> Sample collection and processing | F9: PHA4GE | G9: environmental site | H9: Daycare facility | I9: sites | K9: sampleShed | L9: sampleShed:cdc | P9: In ID generator: Map to sampleShed if preceded by "sampleShed:", map to siteType if preceded by "siteType:". If siteType is already populated from "wastewater system type", then "wastewater system type" takes precedence
A10: 293 | B10: TRUE | C10: TRUE | D10: Sample collection and processing | E10: =IF(G10<>"",VLOOKUP(G10,PHA4GEVars!$A$7:$B$241,2,FALSE),"") -> Sample collection and processing | F10: PHA4GE | G10: environmental site | H10: School | I10: sites | K10: sampleShed | L10: sampleShed:school | P10: In ID generator: Map to sampleShed if preceded by "sampleShed:", map to siteType if preceded by "siteType:". If siteType is already populated from "wastewater system type", then "wastewater system type" takes precedence
A11: 294 | B11: TRUE | C11: TRUE | D11: Sample collection and processing | E11: =IF(G11<>"",VLOOKUP(G11,PHA4GEVars!$A$7:$B$241,2,FALSE),"") -> Sample collection and processing | F11: PHA4GE | G11: environmental site | H11: College or university | I11: sites | K11: sampleShed | L11: sampleShed:uCampus | P11: In ID generator: Map to sampleShed if preceded by "sampleShed:", map to siteType if preceded by "siteType:". If siteType is already populated from "wastewater system type", then "wastewater system type" takes precedence
A12: 295 | B12: TRUE | C12: TRUE | D12: Sample collection and processing | E12: =IF(G12<>"",VLOOKUP(G12,PHA4GEVars!$A$7:$B$241,2,FALSE),"") -> Sample collection and processing | F12: PHA4GE | G12: environmental site | H12: Residential building | I12: sites | K12: sampleShed | L12: sampleShed:orb | P12: In ID generator: Map to sampleShed if preceded by "sampleShed:", map to siteType if preceded by "siteType:". If siteType is already populated from "wastewater system type", then "wastewater system type" takes precedence
A13: 296 | B13: TRUE | C13: TRUE | D13: Sample collection and processing | E13: =IF(G13<>"",VLOOKUP(G13,PHA4GEVars!$A$7:$B$241,2,FALSE),"") -> Sample collection and processing | F13: PHA4GE | G13: environmental site | H13: Homeless shelter | I13: sites | K13: sampleShed | L13: sampleShed:sss | P13: In ID generator: Map to sampleShed if preceded by "sampleShed:", map to siteType if preceded by "siteType:". If siteType is already populated from "wastewater system type", then "wastewater system type" takes precedence
A14: 297 | B14: TRUE | C14: TRUE | D14: Sample collection and processing | E14: =IF(G14<>"",VLOOKUP(G14,PHA4GEVars!$A$7:$B$241,2,FALSE),"") -> Sample collection and processing | F14: PHA4GE | G14: environmental site | H14: Long-term care facility | I14: sites | K14: sampleShed | L14: sampleShed:ltcfAl | P14: In ID generator: Map to sampleShed if preceded by "sampleShed:", map to siteType if preceded by "siteType:". If siteType is already populated from "wastewater system type", then "wastewater system type" takes precedence
A15: 298 | B15: TRUE | C15: TRUE | D15: Sample collection and processing | E15: =IF(G15<>"",VLOOKUP(G15,PHA4GEVars!$A$7:$B$241,2,FALSE),"") -> Sample collection and processing | F15: PHA4GE | G15: environmental site | H15: Transport hub | I15: sites | K15: sampleShed | L15: sampleShed:tHub | P15: In ID generator: Map to sampleShed if preceded by "sampleShed:", map to siteType if preceded by "siteType:". If siteType is already populated from "wastewater system type", then "wastewater system type" takes precedence
... A39: 322 | B39: TRUE | C39: TRUE | D39: Sample collection and processing | E39: =IF(G39<>"",VLOOKUP(G39,PHA4GEVars!$A$7:$B$241,2,FALSE),"") -> Sample collection and processing | F39: PHA4GE | G39: environmental site | H39: Wastewater treatment plant | I39: sites | K39: sampleShed | L39: siteType:wwtp | P39: In ID generator: Map to sampleShed if preceded by "sampleShed:", map to siteType if preceded by "siteType:". If siteType is already populated from "wastewater system type", then "wastewater system type" takes precedence
E40: =IF(G40<>"",VLOOKUP(G40,PHA4GEVars!$A$7:$B$241,2,FALSE),"")
A41: 333 | B41: TRUE | C41: TRUE | D41: Sample collection and processing | E41: =IF(G41<>"",VLOOKUP(G41,PHA4GEVars!$A$7:$B$241,2,FALSE),"") -> Sample collection and processing | F41: PHA4GE | G41: geo loc latitude | H41: NA | I41: sites | K41: geoLat | L41: {{geo loc latitude}}
A42: 334 | B42: TRUE | C42: TRUE | D42: Sample collection and processing | E42: =IF(G42<>"",VLOOKUP(G42,PHA4GEVars!$A$7:$B$241,2,FALSE),"") -> Sample collection and processing | F42: PHA4GE | G42: geo loc longitude | H42: NA | I42: sites | K42: geoLong | L42: {{geo loc longitude}}
A43: 336 | B43: TRUE | C43: TRUE | D43: Sample collection and processing | E43: =IF(G43<>"",VLOOKUP(G43,PHA4GEVars!$A$7:$B$241,2,FALSE),"") -> Sample collection and processing | F43: PHA4GE | G43: geo loc name (site) | H43: NA | I43: sites | K43: name | L43: {{geo_loc name (site)}}
E44: =IF(G44<>"",VLOOKUP(G44,PHA4GEVars!$A$7:$B$241,2,FALSE),"")
A45: 680 | D45: Sample collection and processing | E45: =IF(G45<>"",VLOOKUP(G45,PHA4GEVars!$A$7:$B$241,2,FALSE),"") -> Sample collection and processing | F45: PHA4GE | G45: wastewater system type | H45: Combined sewer system | I45: sites | K45: siteType | L45: wwtpMuC | O45: Need to cross reference with the {{environmental site}} field | P45: "environmental site" maps to same slot (siteType+sampleShed)
A46: 681 | D46: Sample collection and processing | E46: =IF(G46<>"",VLOOKUP(G46,PHA4GEVars!$A$7:$B$241,2,FALSE),"") -> Sample collection and processing | F46: PHA4GE | G46: wastewater system type | H46: Sanitary sewer system | I46: sites | K46: siteType | L46: wwtpMuS | O46: Need to cross reference with the {{environmental site}} field | P46: "environmental site" maps to same slot (siteType+sampleShed)
A47: 682 | D47: Sample collection and processing | E47: =IF(G47<>"",VLOOKUP(G47,PHA4GEVars!$A$7:$B$241,2,FALSE),"") -> Sample collection and processing | F47: PHA4GE | G47: wastewater system type | H47: Sewer (drain) | I47: sites | K47: siteType | L47: drain | O47: Need to cross reference with the {{environmental site}} field | P47: "environmental site" maps to same slot (siteType+sampleShed)
A48: 683 | D48: Sample collection and processing | E48: =IF(G48<>"",VLOOKUP(G48,PHA4GEVars!$A$7:$B$241,2,FALSE),"") -> Sample collection and processing | F48: PHA4GE | G48: wastewater system type | H48: Waste stabilization pond | I48: sites | K48: siteType | L48: stabPnd | O48: Need to cross reference with the {{environmental site}} field | P48: "environmental site" maps to same slot (siteType+sampleShed)
A49: 684 | D49: Sample collection and processing | E49: =IF(G49<>"",VLOOKUP(G49,PHA4GEVars!$A$7:$B$241,2,FALSE),"") -> Sample collection and processing | F49: PHA4GE | G49: wastewater system type | H49: Latrine | I49: sites | K49: siteType | L49: latrine | O49: Need to cross reference with the {{environmental site}} field | P49: "environmental site" maps to same slot (siteType+sampleShed)
A50: 685 | D50: Sample collection and processing | E50: =IF(G50<>"",VLOOKUP(G50,PHA4GEVars!$A$7:$B$241,2,FALSE),"") -> Sample collection and processing | F50: PHA4GE | G50: wastewater system type | H50: Septic tank | I50: sites | K50: siteType | L50: septTnk | O50: Need to cross reference with the {{environmental site}} field | P50: "environmental site" maps to same slot (siteType+sampleShed)
A51: 686 | D51: Sample collection and processing | E51: =IF(G51<>"",VLOOKUP(G51,PHA4GEVars!$A$7:$B$241,2,FALSE),"") -> Sample collection and processing | F51: PHA4GE | G51: wastewater system type | H51: Cesspit | I51: sites | K51: siteType | L51: cesspit | O51: Need to cross reference with the {{environmental site}} field | P51: "environmental site" maps to same slot (siteType+sampleShed)
A52: 687 | D52: Sample collection and processing | E52: =IF(G52<>"",VLOOKUP(G52,PHA4GEVars!$A$7:$B$241,2,FALSE),"") -> Sample collection and processing | F52: PHA4GE | G52: wastewater system type | H52: Composting toilet | I52: sites | K52: siteType | L52: compToi | O52: Need to cross reference with the {{environmental site}} field | P52: "environmental site" maps to same slot (siteType+sampleShed)

Sheet maps_samples
A1: IndexNum | B1: Martin Complete | C1: Complete | D1: PHA4GE_table | E1: PHA4GE Class | F1: sourceClass | G1: sourceSlot | H1: sourceValue | I1: targetClass | J1: targetSlot | K1: targetValue | L1: targetExpr | M1: notes2 | N1: customData | O1: notes | P1: Martin notes
B2: TRUE | C2: TRUE | D2: Sample collection and processing | E2: =IF(G2<>"",VLOOKUP(G2,PHA4GEVars!$A$7:$B$241,2,FALSE),"") -> Sample collection and processing | F2: PHA4GE | G2: collection device | I2: samples | J2: collType | L2: if len([d for d in emap.collection_device if len(d) > 0]): target = emap.collection_device else: target = emap.collection_method # case((collection_device != "", collection_device), (True, collection_method)) | O2: Collection device and collection method are collapsed into a single field, generally, within the ODM. So when both are being mapped to collType, the {{collection Device}} value should supercede {{collection method}}, but here the collection method should match with a value of "Grab Sampling". | R2: case((collection_device == "", collection_method), (True, collection_device))
A3: 261 | B3: TRUE | C3: FALSE | D3: Sample collection and processing | E3: =IF(G3<>"",VLOOKUP(G3,PHA4GEVars!$A$7:$B$241,2,FALSE),"") -> Sample collection and processing | F3: PHA4GE | G3: collection method | I3: samples | J3: collType | O3: See notes for the {{Collection Device.Grab Sampler}} entry.
A4: 267 | B4: TRUE | C4: TRUE | D4: Sample collection and processing | E4: =IF(G4<>"",VLOOKUP(G4,PHA4GEVars!$A$7:$B$241,2,FALSE),"") -> Sample collection and processing | F4: PHA4GE | G4: environmental material | I4: samples | J4: saMaterial | O4: match to sampleID entry row | P4: Which sampleID row?
A5: 325 | B5: TRUE | C5: TRUE | D5: Sample collection and processing | E5: =IF(G5<>"",VLOOKUP(G5,PHA4GEVars!$A$7:$B$241,2,FALSE),"") -> Sample collection and processing | F5: PHA4GE | G5: experimental specimen role type | I5: samples | J5: repType
A6: 622 | D6: Sample collection and processing | E6: =IF(G6<>"",VLOOKUP(G6,PHA4GEVars!$A$7:$B$241,2,FALSE),"") -> Sample collection and processing | F6: PHA4GE | G6: purpose of sampling | I6: samples | J6: purposeID | O6: match to sampleID entry row; plus add compartment = "wat" (depending on enum value) | P6: Add compartment = "wat" (depending on enum value) and match to the sampleID row. No purposeID in samples table
E7: =IF(G7<>"",VLOOKUP(G7,PHA4GEVars!$A$7:$B$241,2,FALSE),"")
A8: 629 | B8: TRUE | C8: TRUE | D8: Sample collection and processing | E8: =IF(G8<>"",VLOOKUP(G8,PHA4GEVars!$A$7:$B$241,2,FALSE),"") -> Sample collection and processing | F8: PHA4GE | G8: sample collected by | I8: samples | J8: organizationID | K8: {{sample collected by}} | O8: Ultimately for each row in the PHA4GE data, there may be up to 4 rows generated in the "contacts" ODM table. 1) Sample collector, 2) sequenced by, 3) sequence submitted by, and 4) isolated by. Complementary contacts metadata need to be grouped together under these ubrellas, but still be separate rows. Furthermore, the "sequenced by/sequence submitted by/isolated by contactIDs should be linked to the measures table, while the sample collector contactID should link to the samples table.
A9: 631 | B9: TRUE | C9: TRUE | D9: Sample collection and processing | E9: =IF(G9<>"",VLOOKUP(G9,PHA4GEVars!$A$7:$B$241,2,FALSE),"") -> Sample collection and processing | F9: PHA4GE | G9: sample collection date | I9: samples | J9: collDT | L9: sample_collection_start_date + '/!/' + sample_collection_start_time + '/!/' | O9: Date and time are separated values here, whereas in the ODM they are recorded together. So "sample collection date" needs to be combined with sample collection start time (if available), and "sample collection end date" and "sample collection end time" need to be combined. In situations where a categorical time of day is reported rather than a precise time, the date should be recorded separately in the {{samples_collDate}} field in ODM. | P9: combine "sample collection date" and "sample collection start time". Changed sample_collection_date to sample_collection_start_date
A10: 632 | B10: TRUE | C10: TRUE | D10: Sample collection and processing | E10: =IF(G10<>"",VLOOKUP(G10,PHA4GEVars!$A$7:$B$241,2,FALSE),"") -> Sample collection and processing | F10: PHA4GE | G10: sample collection end date | I10: samples | J10: collDTEnd | L10: sample_collection_end_date + '/!/' + sample_collection_end_time + '/!/' | O10: Date and time are separated values here, whereas in the ODM they are recorded together. So "sample collection date" needs to be combined with sample collection start time (if available), and "sample collection end date" and "sample collection end time" need to be combined. | P10: Combine "sample collection end date" and "sample collection end time"
A11: 634 | B11: TRUE | C11: TRUE | D11: Sample collection and processing | E11: =IF(G11<>"",VLOOKUP(G11,PHA4GEVars!$A$7:$B$241,2,FALSE),"") -> Sample collection and processing | F11: PHA4GE | G11: sample collection start time | I11: samples | J11: collDTStart | L11: sample_collection_start_date + '/!/' + sample_collection_start_time + '/!/'
E12: =IF(G12<>"",VLOOKUP(G12,PHA4GEVars!$A$7:$B$241,2,FALSE),"")
A13: 643 | D13: Sample collection and processing | E13: =IF(G13<>"",VLOOKUP(G13,PHA4GEVars!$A$7:$B$241,2,FALSE),"") -> Sample collection and processing | F13: PHA4GE | G13: sample collection time of day | H13: Morning | I13: samples | J13: collAppxT | K13: morn | O13: Need to find out how to report time as blank, but not date, inside a datetime variable to link here. | P13: See notes
A14: 644 | D14: Sample collection and processing | E14: =IF(G14<>"",VLOOKUP(G14,PHA4GEVars!$A$7:$B$241,2,FALSE),"") -> Sample collection and processing | F14: PHA4GE | G14: sample collection time of day | H14: Afternoon | I14: samples | J14: collAppxT | K14: aft | O14: Need to find out how to report time as blank, but not date, inside a datetime variable to link here. | P14: See notes
A15: 645 | D15: Sample collection and processing | E15: =IF(G15<>"",VLOOKUP(G15,PHA4GEVars!$A$7:$B$241,2,FALSE),"") -> Sample collection and processing | F15: PHA4GE | G15: sample collection time of day | H15: Evening | I15: samples | J15: collAppxT | K15: eve | O15: Need to find out how to report time as blank, but not date, inside a datetime variable to link here. | P15: See notes
A16: 646 | D16: Sample collection and processing | E16: =IF(G16<>"",VLOOKUP(G16,PHA4GEVars!$A$7:$B$241,2,FALSE),"") -> Sample collection and processing | F16: PHA4GE | G16: sample collection time of day | H16: Night | I16: samples | J16: collAppxT | K16: night | O16: Need to find out how to report time as blank, but not date, inside a datetime variable to link here. | P16: See notes
E17: =IF(G17<>"",VLOOKUP(G17,PHA4GEVars!$A$7:$B$241,2,FALSE),"")
A18: 649 | B18: TRUE | C18: TRUE | D18: Sample collection and processing | E18: =IF(G18<>"",VLOOKUP(G18,PHA4GEVars!$A$7:$B$241,2,FALSE),"") -> Sample collection and processing | F18: PHA4GE | G18: sample received date | I18: samples | J18: recDate | K18: {{sample received date}}
E19: =IF(G19<>"",VLOOKUP(G19,PHA4GEVars!$A$7:$B$241,2,FALSE),"")
A20: 677 | D20: Sample collection and processing | E20: =IF(G20<>"",VLOOKUP(G20,PHA4GEVars!$A$7:$B$241,2,FALSE),"") -> Sample collection and processing | F20: PHA4GE | G20: specimen processing | H20: Technical replicate process | I20: samples | J20: sampleID | K20: {{gernerate new sampleID and new row for this technical replicate}} | O20: also in new row populate repType as "techRep"; link to original sampleID as a "lcsd" through the sample relationships table. | P20: Not sure about notes; These need their own wide row: Do they also inherit all the values found in maps_samples?
A21: 678 | D21: Sample collection and processing | E21: =IF(G21<>"",VLOOKUP(G21,PHA4GEVars!$A$7:$B$241,2,FALSE),"") -> Sample collection and processing | F21: PHA4GE | G21: specimen processing | H21: Biological replicate process | I21: samples | J21: sampleID | K21: {{gernerate new sampleID and new row for this biological replicate}} | O21: also in new row populate repType as "bioRep"; link to original sampleID as a "lcsd" through the sample relationships table. | P21: Not sure about notes; These need their own wide row: Do they also inherit all the values found in maps_samples?
E22: =IF(G22<>"",VLOOKUP(G22,PHA4GEVars!$A$7:$B$241,2,FALSE),"")
A23: 832 | B23: FALSE | C23: FALSE | D23: Strain and isolation information | E23: =IF(G23<>"",VLOOKUP(G23,PHA4GEVars!$A$7:$B$241,2,FALSE),"") -> Strain and isolation information | F23: PHA4GE | G23: isolate received date | I23: samples | J23: recDate | K23: {{isolate received date}} | O23: Isolates should be a separate sample from the original sample, but unified via a child relationship in the samples relationships table. Alternative and regular isolate ID samples table entries should match and be linked with a relationship of "duplicate" where applicable. | P23: See notes; Is not in PHA4GE schema for Sars-Cov2 but is in schema for WastewaterPathogenAgnostic

Sheet wide_samples
A1: Complete | B1: PHA4GE Class | C1: sourceClass | D1: sourceSlot | E1: sourceValue | F1: targetClass | G1: wideOtherSlots | H1: match:sampleID | I1: recDate_value | J1: repType_expr | K1: collPer_expr | L1: sampleID_value | M1: notes
A2: TRUE | B2: =IF(D2<>"",VLOOKUP(D2,PHA4GEVars!$A$7:$B$241,2,FALSE),"") -> Database identifiers | C2: PHA4GE | D2: pooled sample ID | F2: samples | G2: { "pooled_value": true } | H2: pooled sample ID | L2: {{pooled sample ID}} | M2: also populate 'pooled' with 'TRUE'; need to be linked to original sample ID through the relationships table with a "child" relationship (this pooled sample is child).
A3: TRUE | B3: =IF(D3<>"",VLOOKUP(D3,PHA4GEVars!$A$7:$B$241,2,FALSE),"") -> Database identifiers | C3: PHA4GE | D3: sampling event ID | F3: samples | H3: sampling event ID | J3: "sampleEvent" | L3: {{sampling event ID}} | M3: also populate 'repType' with 'sampleEvent'; need to be linked to original sample ID through the relationships table with a "child" relationship, where the original sample is the "child" of this sample.
A4: TRUE | B4: =IF(D4<>"",VLOOKUP(D4,PHA4GEVars!$A$7:$B$241,2,FALSE),"") -> Database identifiers | C4: PHA4GE | D4: specimen collector sample ID | F4: samples | G4: { "saMaterial_value": "{{environmental material}}", "repType_value": "{{experimental specimen role type}}", "organizationID_value": "{{sample collected by}}", "collDT_expr": "sample_collection_start_date + '/!/' + sample_collection_start_time", "collDTStart_expr": "sample_collection_start_time", "collDTEnd_expr": "sample_collection_end_date + '/!/' + sample_collection_end_time" } | H4: specimen collector sample ID | I4: {{sample received date}} | K4: # Convert _value to hours try: _value = float(src.sample_collection_time_duration_value) _unit = src.sample_collection_time_duration_unit.split("[")[0].strip() if _unit == "Second": target = _value / 60 / 60 elif _unit == "Minute": target = _value / 60 elif _unit == "Hour": target = _value elif _unit == "Day": target = _value * 24 elif _unit == "Week": target = _value * 24 * 7 elif _unit == "Month": target = _value * 24 * 7 * 30 elif _unit == "Year": target = _value * 24 * 7 * 365 else: target = "" raise ValueError("Unrecognized value for sample_collection_time_duration_unit in custom mapping spreadsheet (for collPer): " + _unit) except: target = "" | L4: {{specimen collector sample ID}} | M4: wideOtherSlots had purposeID that does not exist in samples table: "purposeID_value": "{{purpose of sampling}}",
A5: TRUE | B5: =IF(D5<>"",VLOOKUP(D5,PHA4GEVars!$A$7:$B$241,2,FALSE),"") -> Database identifiers | C5: PHA4GE | D5: specimen collector subsample ID | F5: samples | H5: specimen collector subsample ID | J5: "subSamp" | L5: {{specimen collector subsample ID}} | M5: also populate 'repType' with 'subSamp'; need to be linked to original sample ID through the relationships table with a "child" relationship (this subsample is child).
A6: TRUE | B6: =IF(D6<>"",VLOOKUP(D6,PHA4GEVars!$A$7:$B$241,2,FALSE),"") -> Strain and isolation information | C6: PHA4GE | D6: alternative isolate ID | F6: samples | H6: alternative isolate ID | L6: {{alternative isolate ID}} | M6: Isolates should be a separate sample from the original sample, but unified via a child relationship in the samples relationships table. Alternative and regular isolate ID samples table entries should match and be linked with a relationship of "duplicate" where applicable.
A7: TRUE | B7: =IF(D7<>"",VLOOKUP(D7,PHA4GEVars!$A$7:$B$241,2,FALSE),"") -> Strain and isolation information | C7: PHA4GE | D7: isolate ID | F7: samples | G7: { "collDT_value": "{{isolation date}}" } | H7: isolate ID | I7: {{isolate received date}} | L7: {{isolate ID}} | M7: Isolates should be a separate sample from the original sample, but unified via a child relationship in the samples relationships table. Alternative and regular isolate ID samples table entries should match and be linked with a relationship of "duplicate" where applicable.
A8: TRUE | B8: =IF(D8<>"",VLOOKUP(D8,PHA4GEVars!$A$7:$B$241,2,FALSE),"") -> Strain and isolation information | C8: PHA4GE | D8: progeny isolate ID | F8: samples | H8: progeny isolate ID | L8: {{progeny isolate ID}} | M8: This new sample ID needs to be linked to the original sample ID with a parent/child relationship ID>

Sheet maps_measures
A1: IndexNum | B1: Martin Complete | C1: Complete | D1: selectors | E1: PHA4GE_table | F1: PHA4GE Class | G1: sourceClass | H1: sourceSlot | I1: sourceValue | J1: targetClass | K1: wide? | L1: targetSlot | M1: targetValue | N1: targetExpr | O1: notes2 | P1: customData | Q1: notes | R1: Martin notes
A2: 1 | B2: TRUE | C2: TRUE | D2: amr | E2: AMR detection information | F2: =IF(H2<>"",VLOOKUP(H2,PHA4GEVars!$A$7:$B$241,2,FALSE),"") -> AMR detection information | G2: PHA4GE | H2: AMR analysis report filename | I2: NA | J2: measures | L2: notes | M2: {{AMR analysis report filename}} | Q2: Add to the measure row of an AMR target in the notes field. | R2: Only found in PHA4GE WastewaterAMR schema
F3: =IF(H3<>"",VLOOKUP(H3,PHA4GEVars!$A$7:$B$241,2,FALSE),"")
A4: 26 | E4: Bioinformatics and QC metrics | F4: =IF(H4<>"",VLOOKUP(H4,PHA4GEVars!$A$7:$B$241,2,FALSE),"") -> Bioinformatics and QC metrics | G4: PHA4GE | H4: quality control determination | I4: no quality control issues identified | J4: measures | L4: reportable | M4: TRUE
A5: 27 | E5: Bioinformatics and QC metrics | F5: =IF(H5<>"",VLOOKUP(H5,PHA4GEVars!$A$7:$B$241,2,FALSE),"") -> Bioinformatics and QC metrics | G5: PHA4GE | H5: quality control determination | I5: sequence passed quality control | J5: measures | L5: reportable | M5: TRUE | Q5: report with sequencing measure | R5: See notes
A6: 28 | E6: Bioinformatics and QC metrics | F6: =IF(H6<>"",VLOOKUP(H6,PHA4GEVars!$A$7:$B$241,2,FALSE),"") -> Bioinformatics and QC metrics | G6: PHA4GE | H6: quality control determination | I6: sequence failed quality control | J6: measures | L6: reportable | M6: FALSE | Q6: report with sequencing measure | R6: See notes
A7: 29 | E7: Bioinformatics and QC metrics | F7: =IF(H7<>"",VLOOKUP(H7,PHA4GEVars!$A$7:$B$241,2,FALSE),"") -> Bioinformatics and QC metrics | G7: PHA4GE | H7: quality control determination | I7: minor quality control issues identified | J7: measures | L7: reportable | M7: TRUE | Q7: Generate a quality report with the the quality flag "qf1" to accompany this report, and then report both with the sequencing measure | R7: See notes
A8: 30 | E8: Bioinformatics and QC metrics | F8: =IF(H8<>"",VLOOKUP(H8,PHA4GEVars!$A$7:$B$241,2,FALSE),"") -> Bioinformatics and QC metrics | G8: PHA4GE | H8: quality control determination | I8: sequence flagged for potential quality control issues | J8: measures | L8: reportable | M8: TRUE | Q8: Generate a quality report with the the quality flag "qf1" to accompany this report, and then report both with the sequencing measure | R8: See notes
A9: 31 | E9: Bioinformatics and QC metrics | F9: =IF(H9<>"",VLOOKUP(H9,PHA4GEVars!$A$7:$B$241,2,FALSE),"") -> Bioinformatics and QC metrics | G9: PHA4GE | H9: quality control determination | I9: quality control not performed | J9: measures | L9: reportable | M9: nr | Q9: report with sequencing measure | R9: See notes
F10: =IF(H10<>"",VLOOKUP(H10,PHA4GEVars!$A$7:$B$241,2,FALSE),"")
A11: 247 | E11: Pathogen diagnostic testing | F11: =IF(H11<>"",VLOOKUP(H11,PHA4GEVars!$A$7:$B$241,2,FALSE),"") -> Pathogen diagnostic testing | G11: PHA4GE | H11: gene name | J11: measures | L11: measure | M11: {{gene name}} | Q11: should really be reported in the same row as the measure - the trouble here too is that the organism field here is ostensibly freetext, whereas the ODM field is categorical. | R11: gene name is recorded in multiple rows in wide_measures. Should it be reported elsewhere as well?
A12: 248 | B12: TRUE | C12: TRUE | E12: Pathogen diagnostic testing | F12: =IF(H12<>"",VLOOKUP(H12,PHA4GEVars!$A$7:$B$241,2,FALSE),"") -> Sample collection and processing | G12: PHA4GE | H12: organism | I12: NA | J12: measures | L12: group | M12: {{organism}} | Q12: should really be reported in the same row as the measure - the trouble here too is that the organism field here is ostensibly freetext, whereas the ODM field is categorical. | R12: Is this the group value for all output rows in the measures table? (that's the current behavior); Has a conflict with sourceTable=Sample collection and processing, sourceSlot=organism (in another row)
A13: 266 | E13: Sample collection and processing | F13: =IF(H13<>"",VLOOKUP(H13,PHA4GEVars!$A$7:$B$241,2,FALSE),"") -> Sample collection and processing | G13: PHA4GE | H13: endogenous control details | I13: NA | J13: measures | K13: wide_value | Q13: Needs to be linked to the main measure report, probably through a measure set. Ideally purpose would also be populated with "normalization". | R13: Row in wide_measures seems incorrect
A14: 610 | E14: Sample collection and processing | F14: =IF(H14<>"",VLOOKUP(H14,PHA4GEVars!$A$7:$B$241,2,FALSE),"") -> Sample collection and processing | G14: PHA4GE | H14: organism | I14: NA | J14: measures | L14: group | M14: {{organism}} | Q14: Unfortunately may need regex because it needs to match a valid "group" type part in the "parts" table. | R14: See notes; has conflict with other row where sourceTable=Pathogen diagnostic testing, sourceSlot=organism
F15: =IF(H15<>"",VLOOKUP(H15,PHA4GEVars!$A$7:$B$241,2,FALSE),"")
A16: 720 | E16: Sequence information | F16: =IF(H16<>"",VLOOKUP(H16,PHA4GEVars!$A$7:$B$241,2,FALSE),"") -> Sequence information | G16: PHA4GE | H16: purpose of sequencing | I16: Baseline surveillance (random sampling) | J16: measures | L16: purposeID | M16: Random sampling surveillance program | Q16: match to measureRepID entry row | R16: See notes, no purposeID in measures table
A17: 721 | E17: Sequence information | F17: =IF(H17<>"",VLOOKUP(H17,PHA4GEVars!$A$7:$B$241,2,FALSE),"") -> Sequence information | G17: PHA4GE | H17: purpose of sequencing | I17: Targeted surveillance (non-random sampling) | J17: measures | L17: purposeID | M17: Targeted surveillance program | Q17: match to measureRepID entry row | R17: See notes, no purposeID in measures table
A18: 722 | E18: Sequence information | F18: =IF(H18<>"",VLOOKUP(H18,PHA4GEVars!$A$7:$B$241,2,FALSE),"") -> Sequence information | G18: PHA4GE | H18: purpose of sequencing | I18: Priority surveillance project | J18: measures | L18: purposeID | M18: Emergency targetted surveillance program | Q18: match to measureRepID entry row | R18: See notes, no purposeID in measures table
A19: 723 | E19: Sequence information | F19: =IF(H19<>"",VLOOKUP(H19,PHA4GEVars!$A$7:$B$241,2,FALSE),"") -> Sequence information | G19: PHA4GE | H19: purpose of sequencing | I19: Longitudinal surveillance (repeat sampling) | J19: measures | L19: purposeID | M19: Longitudinal, repeat sampling surveillance program | Q19: match to measureRepID entry row | R19: See notes, no purposeID in measures table
A20: 724 | E20: Sequence information | F20: =IF(H20<>"",VLOOKUP(H20,PHA4GEVars!$A$7:$B$241,2,FALSE),"") -> Sequence information | G20: PHA4GE | H20: purpose of sequencing | I20: Travel-associated surveillance | J20: measures | L20: purposeID | M20: Travel hub surveillance - general | Q20: match to measureRepID entry row | R20: See notes, no purposeID in measures table
A21: 725 | E21: Sequence information | F21: =IF(H21<>"",VLOOKUP(H21,PHA4GEVars!$A$7:$B$241,2,FALSE),"") -> Sequence information | G21: PHA4GE | H21: purpose of sequencing | I21: Domestic travel surveillance | J21: measures | L21: purposeID | M21: Domestic travel hub surveillance | Q21: match to measureRepID entry row | R21: See notes, no purposeID in measures table
A22: 726 | E22: Sequence information | F22: =IF(H22<>"",VLOOKUP(H22,PHA4GEVars!$A$7:$B$241,2,FALSE),"") -> Sequence information | G22: PHA4GE | H22: purpose of sequencing | I22: International travel surveillance | J22: measures | L22: purposeID | M22: International travel hub surveillance | Q22: match to measureRepID entry row | R22: See notes, no purposeID in measures table
A23: 727 | E23: Sequence information | F23: =IF(H23<>"",VLOOKUP(H23,PHA4GEVars!$A$7:$B$241,2,FALSE),"") -> Sequence information | G23: PHA4GE | H23: purpose of sequencing | I23: Research | J23: measures | L23: purposeID | M23: researchPurp | Q23: match to measureRepID entry row | R23: See notes, no purposeID in measures table
A24: 728 | E24: Sequence information | F24: =IF(H24<>"",VLOOKUP(H24,PHA4GEVars!$A$7:$B$241,2,FALSE),"") -> Sequence information | G24: PHA4GE | H24: purpose of sequencing | I24: Viral passage experiment | J24: measures | L24: purposeID | M24: viralPass | Q24: match to measureRepID entry row | R24: See notes, no purposeID in measures table
A25: 729 | E25: Sequence information | F25: =IF(H25<>"",VLOOKUP(H25,PHA4GEVars!$A$7:$B$241,2,FALSE),"") -> Sequence information | G25: PHA4GE | H25: purpose of sequencing | I25: Protocol testing experiment | J25: measures | L25: purposeID | M25: testing | Q25: match to measureRepID entry row | R25: See notes, no purposeID in measures table
F26: =IF(H26<>"",VLOOKUP(H26,PHA4GEVars!$A$7:$B$241,2,FALSE),"")
A27: 730 | E27: Sequence information | F27: =IF(H27<>"",VLOOKUP(H27,PHA4GEVars!$A$7:$B$241,2,FALSE),"") -> Sequence information | G27: PHA4GE | H27: purpose of sequencing details | J27: measures | L27: notes | M27: {{purpose of sequencing details}} | Q27: add to sequencing measure report | R27: See notes
A28: 848 | E28: Taxonomic identification information | F28: =IF(H28<>"",VLOOKUP(H28,PHA4GEVars!$A$7:$B$241,2,FALSE),"") -> Taxonomic identification information | G28: PHA4GE | H28: taxonomic analysis report filename | I28: NA | J28: measures | L28: notes | M28: {{taxonomic analysis report filename}} | Q28: Add to the measure row of a taxonomy measure in the notes field.
F29: =IF(H29<>"",VLOOKUP(H29,PHA4GEVars!$A$7:$B$241,2,FALSE),"")
F30: =IF(H30<>"",VLOOKUP(H30,PHA4GEVars!$A$7:$B$241,2,FALSE),"") -> Database identifiers | G30: PHA4GE | H30: sampling site ID | J30: measures | L30: siteID | M30: {{sampling site ID}}
A32: 648 | E32: Sample collection and processing | F32: =IF(H32<>"",VLOOKUP(H32,PHA4GEVars!$A$7:$B$241,2,FALSE),"") -> Sample collection and processing | G32: PHA4GE | H32: sample processing date | I32: NA | J32: measures | L32: aDateEnd | M32: {{sample processing date}} | Q32: May need to be revisitted as a mapping because of duplicate targets - link to extraction recovery measure maybe?
A33: 741 | E33: Sequence information | F33: =IF(H33<>"",VLOOKUP(H33,PHA4GEVars!$A$7:$B$241,2,FALSE),"") -> Sequence information | G33: PHA4GE | H33: sequencing date | I33: NA | J33: measures | L33: aDateEnd | M33: {{sequencing date}} | Q33: match to measureRepID entry row for sequencing | R33: See notes
A34: 847 | E34: Taxonomic identification information | F34: =IF(H34<>"",VLOOKUP(H34,PHA4GEVars!$A$7:$B$241,2,FALSE),"") -> Taxonomic identification information | G34: PHA4GE | H34: taxonomic analysis date | I34: NA | J34: measures | L34: aDateEnd | M34: {{taxonomic analysis date}}
C36: TRUE | G36: PHA4GE | J36: measures | L36: match:datasetID | N36: "specimen collector project ID"
C37: TRUE | G37: PHA4GE | J37: measures | L37: match:sampleID | N37: "specimen collector sample ID"

Sheet wide_measures
A1: Martin Complete | B1: Complete | C1: PHA4GE Class | D1: sourceClass | E1: sourceSlot | F1: sourceValue | G1: targetClass | H1: targetValue | I1: wideOtherSlots | J1: match:sampleID | K1: match:datasetID | L1: aDateEnd_value | M1: organizationID_value | N1: protocolID_value | O1: specimen_value | P1: measure_value | Q1: measureSetRepID_value | R1: value_value | S1: unit_value | T1: aggregation_value | U1: notes | V1: Martin Notes
A2: TRUE | B2: TRUE | C2: =IF(E2<>"",VLOOKUP(E2,PHA4GEVars!$A$7:$B$241,2,FALSE),"") -> Environmental conditions and measurements | D2: PHA4GE | E2: alkalinity measurement value | G2: measures | N2: {{alkalinity measurement method}} | O2: si | P2: alkaline | R2: {{alkalinity measurement value}} | S2: {{alkalinity measurement unit}} | T2: me | U2: not sure about the aggregation
A3: TRUE | B3: TRUE | C3: =IF(E3<>"",VLOOKUP(E3,PHA4GEVars!$A$7:$B$241,2,FALSE),"") -> Environmental conditions and measurements | D3: PHA4GE | E3: dissolved oxygen measurement value | G3: measures | N3: {{dissolved oxygen measurement method}} | O3: si | P3: dissOxy | R3: {{dissolved oxygen measurement value}} | S3: {{dissolved oxygen measurement unit}} | T3: me | U3: not sure about the aggregation
A4: TRUE | B4: TRUE | C4: =IF(E4<>"",VLOOKUP(E4,PHA4GEVars!$A$7:$B$241,2,FALSE),"") -> Environmental conditions and measurements | D4: PHA4GE | E4: fecal coliform count value | G4: measures | N4: {{fecal coliform count method}} | O4: sa | P4: fecalCol | R4: {{fecal coliform count value}} | S4: {{fecal coliform count unit}} | T4: me | U4: not sure about the aggregation
A5: TRUE | B5: TRUE | C5: =IF(E5<>"",VLOOKUP(E5,PHA4GEVars!$A$7:$B$241,2,FALSE),"") -> Environmental conditions and measurements | D5: PHA4GE | E5: oxygen reduction potential (ORP) measurement value | G5: measures | N5: {{oxygen reduction potential (ORP) measurement method}} | O5: si | P5: orp | R5: {{oxygen reduction potential (ORP) measurement value}} | S5: {{oxygen reduction potential (ORP) measurement unit}} | T5: me | U5: not sure about the aggregation
C6: =IF(E6<>"",VLOOKUP(E6,PHA4GEVars!$A$7:$B$241,2,FALSE),"")
A7: TRUE | B7: TRUE | C7: =IF(E7<>"",VLOOKUP(E7,PHA4GEVars!$A$7:$B$241,2,FALSE),"") -> Environmental conditions and measurements | D7: PHA4GE | E7: populated area type | F7: Suburban | G7: measures | H7: suburban | O7: si | P7: popAreaType | R7: {{populated area type}} | S7: unitless | T7: sin
A8: TRUE | B8: TRUE | C8: =IF(E8<>"",VLOOKUP(E8,PHA4GEVars!$A$7:$B$241,2,FALSE),"") -> Environmental conditions and measurements | D8: PHA4GE | E8: populated area type | F8: Rural | G8: measures | H8: rural | O8: si | P8: popAreaType | R8: {{populated area type}} | S8: unitless | T8: sin
A9: TRUE | B9: TRUE | C9: =IF(E9<>"",VLOOKUP(E9,PHA4GEVars!$A$7:$B$241,2,FALSE),"") -> Environmental conditions and measurements | D9: PHA4GE | E9: populated area type | F9: Urban | G9: measures | H9: urban | O9: si | P9: popAreaType | R9: {{populated area type}} | S9: unitless | T9: sin
C10: =IF(E10<>"",VLOOKUP(E10,PHA4GEVars!$A$7:$B$241,2,FALSE),"")
A11: TRUE | B11: TRUE | C11: =IF(E11<>"",VLOOKUP(E11,PHA4GEVars!$A$7:$B$241,2,FALSE),"") -> Environmental conditions and measurements | D11: PHA4GE | E11: salinity measurement value | G11: measures | N11: {{salinity measurement method}} | O11: si | P11: salinity | R11: {{salinity measurement value}} | S11: {{salinity measurement unit}} | T11: me
A13: TRUE | B13: TRUE | C13: =IF(E13<>"",VLOOKUP(E13,PHA4GEVars!$A$7:$B$241,2,FALSE),"") -> Environmental conditions and measurements | D13: PHA4GE | E13: total dissolved solids (TDS) measurement value | G13: measures | N13: {{total dissolved solids (TDS) measurement method}} | O13: si | P13: tds | R13: {{total dissolved solids (TDS) measurement value}} | S13: {{total dissolved solids (TDS) measurement unit}} | T13: me
C14: =IF(E14<>"",VLOOKUP(E14,PHA4GEVars!$A$7:$B$241,2,FALSE),"")
A15: TRUE | B15: TRUE | C15: =IF(E15<>"",VLOOKUP(E15,PHA4GEVars!$A$7:$B$241,2,FALSE),"") -> #N/A | D15: PHA4GE | E15: water catchment area human population range | F15: <10 people | G15: measures | H15: less10 | O15: si | P15: popServRange | R15: {{water catchment area human population range}} | S15: peeps | T15: me | V15: Might be "water catchment area human population bin"
A16: TRUE | B16: TRUE | C16: =IF(E16<>"",VLOOKUP(E16,PHA4GEVars!$A$7:$B$241,2,FALSE),"") -> #N/A | D16: PHA4GE | E16: water catchment area human population range | F16: 10 - 100 people | G16: measures | H16: less100 | O16: si | P16: popServRange | R16: {{water catchment area human population range}} | S16: peeps | T16: me | V16: Might be "water catchment area human population bin"
A17: TRUE | B17: TRUE | C17: =IF(E17<>"",VLOOKUP(E17,PHA4GEVars!$A$7:$B$241,2,FALSE),"") -> #N/A | D17: PHA4GE | E17: water catchment area human population range | F17: 100 - 1,000 people | G17: measures | H17: less1k | O17: si | P17: popServRange | R17: {{water catchment area human population range}} | S17: peeps | T17: me | V17: Might be "water catchment area human population bin"
A18: TRUE | B18: TRUE | C18: =IF(E18<>"",VLOOKUP(E18,PHA4GEVars!$A$7:$B$241,2,FALSE),"") -> #N/A | D18: PHA4GE | E18: water catchment area human population range | F18: 1,000 - 10,000 people | G18: measures | H18: less10k | O18: si | P18: popServRange | R18: {{water catchment area human population range}} | S18: peeps | T18: me | V18: Might be "water catchment area human population bin"
A19: TRUE | B19: TRUE | C19: =IF(E19<>"",VLOOKUP(E19,PHA4GEVars!$A$7:$B$241,2,FALSE),"") -> #N/A | D19: PHA4GE | E19: water catchment area human population range | F19: 10,000 - 100,000 people | G19: measures | H19: less100k | O19: si | P19: popServRange | R19: {{water catchment area human population range}} | S19: peeps | T19: me | V19: Might be "water catchment area human population bin"
A20: TRUE | B20: TRUE | C20: =IF(E20<>"",VLOOKUP(E20,PHA4GEVars!$A$7:$B$241,2,FALSE),"") -> #N/A | D20: PHA4GE | E20: water catchment area human population range | F20: 100,000 - 1,000,000 people | G20: measures | H20: less1mil | O20: si | P20: popServRange | R20: {{water catchment area human population range}} | S20: peeps | T20: me | V20: Might be "water catchment area human population bin"; An extra space is added after the dash because that's how it is in the PHA4GE schema from Charlie
A21: TRUE | B21: TRUE | C21: =IF(E21<>"",VLOOKUP(E21,PHA4GEVars!$A$7:$B$241,2,FALSE),"") -> #N/A | D21: PHA4GE | E21: water catchment area human population range | F21: 1,000,000+ people | G21: measures | H21: more1mil | O21: si | P21: popServRange | R21: {{water catchment area human population range}} | S21: peeps | T21: me | V21: Might be "water catchment area human population bin"
C22: =IF(E22<>"",VLOOKUP(E22,PHA4GEVars!$A$7:$B$241,2,FALSE),"")
A23: TRUE | B23: TRUE | C23: =IF(E23<>"",VLOOKUP(E23,PHA4GEVars!$A$7:$B$241,2,FALSE),"") -> Environmental conditions and measurements | D23: PHA4GE | E23: water catchment area human population measurement value | G23: measures | N23: {{water catchment area human population measurement method}} | O23: si | P23: popServ | R23: {{water catchment area human population measurement value}} | S23: peeps | T23: me | V23: Used to be "water catchment human population measurement value"
C24: =IF(E24<>"",VLOOKUP(E24,PHA4GEVars!$A$7:$B$241,2,FALSE),"")
A25: TRUE | B25: TRUE | C25: =IF(E25<>"",VLOOKUP(E25,PHA4GEVars!$A$7:$B$241,2,FALSE),"") -> Environmental conditions and measurements | D25: PHA4GE | E25: presampling weather conditions | F25: Cloudy/Overcast | G25: measures | H25: cloudy | O25: si | P25: preSampWeath | R25: {{presampling weather conditions}} | S25: unitless | T25: sin
A26: TRUE | B26: TRUE | C26: =IF(E26<>"",VLOOKUP(E26,PHA4GEVars!$A$7:$B$241,2,FALSE),"") -> Environmental conditions and measurements | D26: PHA4GE | E26: presampling weather conditions | F26: Partially cloudy | G26: measures | H26: cloudy | O26: si | P26: preSampWeath | R26: {{presampling weather conditions}} | S26: unitless | T26: sin
A27: TRUE | B27: TRUE | C27: =IF(E27<>"",VLOOKUP(E27,PHA4GEVars!$A$7:$B$241,2,FALSE),"") -> Environmental conditions and measurements | D27: PHA4GE | E27: presampling weather conditions | F27: Drizzle | G27: measures | H27: rainy | O27: si | P27: preSampWeath | R27: {{presampling weather conditions}} | S27: unitless | T27: sin
A28: TRUE | B28: TRUE | C28: =IF(E28<>"",VLOOKUP(E28,PHA4GEVars!$A$7:$B$241,2,FALSE),"") -> Environmental conditions and measurements | D28: PHA4GE | E28: presampling weather conditions | F28: Fog | G28: measures | H28: foggy | O28: si | P28: preSampWeath | R28: {{presampling weather conditions}} | S28: unitless | T28: sin
A29: TRUE | B29: TRUE | C29: =IF(E29<>"",VLOOKUP(E29,PHA4GEVars!$A$7:$B$241,2,FALSE),"") -> Environmental conditions and measurements | D29: PHA4GE | E29: presampling weather conditions | F29: Rain | G29: measures | H29: rainy | O29: si | P29: preSampWeath | R29: {{presampling weather conditions}} | S29: unitless | T29: sin
A30: TRUE | B30: TRUE | C30: =IF(E30<>"",VLOOKUP(E30,PHA4GEVars!$A$7:$B$241,2,FALSE),"") -> Environmental conditions and measurements | D30: PHA4GE | E30: presampling weather conditions | F30: Snow | G30: measures | H30: snowy | O30: si | P30: preSampWeath | R30: {{presampling weather conditions}} | S30: unitless | T30: sin
A31: TRUE | B31: TRUE | C31: =IF(E31<>"",VLOOKUP(E31,PHA4GEVars!$A$7:$B$241,2,FALSE),"") -> Environmental conditions and measurements | D31: PHA4GE | E31: presampling weather conditions | F31: Storm | G31: measures | H31: stormy | O31: si | P31: preSampWeath | R31: {{presampling weather conditions}} | S31: unitless | T31: sin
A32: TRUE | B32: TRUE | C32: =IF(E32<>"",VLOOKUP(E32,PHA4GEVars!$A$7:$B$241,2,FALSE),"") -> Environmental conditions and measurements | D32: PHA4GE | E32: presampling weather conditions | F32: Sunny/Clear | G32: measures | H32: sunny | O32: si | P32: preSampWeath | R32: {{presampling weather conditions}} | S32: unitless | T32: sin
C33: =IF(E33<>"",VLOOKUP(E33,PHA4GEVars!$A$7:$B$241,2,FALSE),"")
A34: TRUE | B34: TRUE | C34: =IF(E34<>"",VLOOKUP(E34,PHA4GEVars!$A$7:$B$241,2,FALSE),"") -> Environmental conditions and measurements | D34: PHA4GE | E34: sampling weather conditions | F34: Cloudy/Overcast | G34: measures | H34: cloudy | O34: si | P34: weath | R34: {{sampling weather conditions}} | S34: unitless | T34: sin
A35: TRUE | B35: TRUE | C35: =IF(E35<>"",VLOOKUP(E35,PHA4GEVars!$A$7:$B$241,2,FALSE),"") -> Environmental conditions and measurements | D35: PHA4GE | E35: sampling weather conditions | F35: Partially cloudy | G35: measures | H35: cloudy | O35: si | P35: weath | R35: {{sampling weather conditions}} | S35: unitless | T35: sin
A36: TRUE | B36: TRUE | C36: =IF(E36<>"",VLOOKUP(E36,PHA4GEVars!$A$7:$B$241,2,FALSE),"") -> Environmental conditions and measurements | D36: PHA4GE | E36: sampling weather conditions | F36: Drizzle | G36: measures | H36: rainy | O36: si | P36: weath | R36: {{sampling weather conditions}} | S36: unitless | T36: sin
A37: TRUE | B37: TRUE | C37: =IF(E37<>"",VLOOKUP(E37,PHA4GEVars!$A$7:$B$241,2,FALSE),"") -> Environmental conditions and measurements | D37: PHA4GE | E37: sampling weather conditions | F37: Fog | G37: measures | H37: foggy | O37: si | P37: weath | R37: {{sampling weather conditions}} | S37: unitless | T37: sin
A38: TRUE | B38: TRUE | C38: =IF(E38<>"",VLOOKUP(E38,PHA4GEVars!$A$7:$B$241,2,FALSE),"") -> Environmental conditions and measurements | D38: PHA4GE | E38: sampling weather conditions | F38: Rain | G38: measures | H38: rainy | O38: si | P38: weath | R38: {{sampling weather conditions}} | S38: unitless | T38: sin
A39: TRUE | B39: TRUE | C39: =IF(E39<>"",VLOOKUP(E39,PHA4GEVars!$A$7:$B$241,2,FALSE),"") -> Environmental conditions and measurements | D39: PHA4GE | E39: sampling weather conditions | F39: Snow | G39: measures | H39: snowy | O39: si | P39: weath | R39: {{sampling weather conditions}} | S39: unitless | T39: sin
A40: TRUE | B40: TRUE | C40: =IF(E40<>"",VLOOKUP(E40,PHA4GEVars!$A$7:$B$241,2,FALSE),"") -> Environmental conditions and measurements | D40: PHA4GE | E40: sampling weather conditions | F40: Storm | G40: measures | H40: stormy | O40: si | P40: weath | R40: {{sampling weather conditions}} | S40: unitless | T40: sin
A41: TRUE | B41: TRUE | C41: =IF(E41<>"",VLOOKUP(E41,PHA4GEVars!$A$7:$B$241,2,FALSE),"") -> Environmental conditions and measurements | D41: PHA4GE | E41: sampling weather conditions | F41: Sunny/Clear | G41: measures | H41: sunny | O41: si | P41: weath | R41: {{sampling weather conditions}} | S41: unitless | T41: sin
...

Sheet wide_measurestest
A1: Martin Complete | B1: Complete | C1: PHA4GE Class | D1: sourceClass | E1: sourceSlot | F1: sourceValue | G1: targetClass | H1: targetValue | I1: wideOtherSlots | J1: match:sampleID | K1: match:datasetID | L1: match:test | M1: aDateEnd_value | N1: organizationID_value | O1: protocolID_value | P1: specimen_value | Q1: measure_value | R1: measureSetRepID_value | S1: value_value | T1: unit_value | U1: aggregation_value | V1: notes | W1: Martin Notes
A2: TRUE | B2: TRUE | C2: =IF(E2<>"",VLOOKUP(E2,PHA4GEVars!$A$7:$B$241,2,FALSE),"") -> Environmental conditions and measurements | D2: PHA4GE | E2: alkalinity measurement value | G2: measures | J2: specimen collector sample ID | K2: specimen collector project ID | L2: <empty> | O2: {{alkalinity measurement method}} | P2: si | Q2: alkaline | S2: {{alkalinity measurement value}} | T2: {{alkalinity measurement unit}} | U2: me | V2: not sure about the aggregation

Sheet enums_samples
A1: IndexNum | B1: Complete | C1: PHA4GE_table | D1: PHA4GE Class | E1: sourceClass | F1: sourceSlot | G1: sourceValue | H1: targetClass | I1: targetSlot-unused | J1: targetValue | K1: exprValue | L1: customData | M1: notes | N1: Martin Notes
A2: 249 | B2: =IF(OR(G2="NA",H2="wide_value"),"",TRUE) -> TRUE | C2: Sample collection and processing | D2: =IF(F2<>"",VLOOKUP(F2,PHA4GEVars!$A$7:$B$241,2,FALSE),"") -> Sample collection and processing | E2: PHA4GE | F2: collection device | G2: Grab sampler | H2: samples | I2: collType | J2: grb | M2: Collection device and collection method are collapsed into a single field, generally, within the ODM. So when both are being mapped to collType, the {{collection Device}} value should supercede {{collection method}}, but here the collection method should match with a value of "Grab Sampling". | N2: Need to make sure "collection device" supercedes "collection method"
A3: 250 | B3: =IF(OR(G3="NA",H3="wide_value"),"",TRUE) -> TRUE | C3: Sample collection and processing | D3: =IF(F3<>"",VLOOKUP(F3,PHA4GEVars!$A$7:$B$241,2,FALSE),"") -> Sample collection and processing | E3: PHA4GE | F3: collection device | G3: Core sampling device | H3: samples | I3: collType | J3: core | M3: Collection device and collection method are collapsed into a single field, generally, within the ODM. So when both are being mapped to collType, the {{collection Device}} value should supercede {{collection method}}, but here the collection method should match with a value of "Grab Sampling".
A4: 251 | B4: =IF(OR(G4="NA",H4="wide_value"),"",TRUE) -> TRUE | C4: Sample collection and processing | D4: =IF(F4<>"",VLOOKUP(F4,PHA4GEVars!$A$7:$B$241,2,FALSE),"") -> Sample collection and processing | E4: PHA4GE | F4: collection device | G4: Vacuum sludge sampling device | H4: samples | I4: collType | J4: vac | M4: Collection device and collection method are collapsed into a single field, generally, within the ODM. So when both are being mapped to collType, the {{collection Device}} value should supercede {{collection method}}, but here the collection method should match with a value of "Grab Sampling".
A5: 252 | B5: =IF(OR(G5="NA",H5="wide_value"),"",TRUE) -> TRUE | C5: Sample collection and processing | D5: =IF(F5<>"",VLOOKUP(F5,PHA4GEVars!$A$7:$B$241,2,FALSE),"") -> Sample collection and processing | E5: PHA4GE | F5: collection device | G5: Cone-shaped sampling device | H5: samples | I5: collType | J5: one | M5: Collection device and collection method are collapsed into a single field, generally, within the ODM. So when both are being mapped to collType, the {{collection Device}} value should supercede {{collection method}}, but here the collection method should match with a value of "Grab Sampling".
A6: 253 | B6: =IF(OR(G6="NA",H6="wide_value"),"",TRUE) -> TRUE | C6: Sample collection and processing | D6: =IF(F6<>"",VLOOKUP(F6,PHA4GEVars!$A$7:$B$241,2,FALSE),"") -> Sample collection and processing | E6: PHA4GE | F6: collection device | G6: Horizontal grab sampling device | H6: samples | I6: collType | J6: horGrb | M6: Collection device and collection method are collapsed into a single field, generally, within the ODM. So when both are being mapped to collType, the {{collection Device}} value should supercede {{collection method}}, but here the collection method should match with a value of "Grab Sampling".
A7: 254 | B7: =IF(OR(G7="NA",H7="wide_value"),"",TRUE) -> TRUE | C7: Sample collection and processing | D7: =IF(F7<>"",VLOOKUP(F7,PHA4GEVars!$A$7:$B$241,2,FALSE),"") -> Sample collection and processing | E7: PHA4GE | F7: collection device | G7: Vertical grab sampling device | H7: samples | I7: collType | J7: vertGrb | M7: Collection device and collection method are collapsed into a single field, generally, within the ODM. So when both are being mapped to collType, the {{collection Device}} value should supercede {{collection method}}, but here the collection method should match with a value of "Grab Sampling".
A8: 255 | B8: =IF(OR(G8="NA",H8="wide_value"),"",TRUE) -> TRUE | C8: Sample collection and processing | D8: =IF(F8<>"",VLOOKUP(F8,PHA4GEVars!$A$7:$B$241,2,FALSE),"") -> Sample collection and processing | E8: PHA4GE | F8: collection device | G8: Composite sampler | H8: samples | I8: collType | J8: comp | M8: Collection device and collection method are collapsed into a single field, generally, within the ODM. So when both are being mapped to collType, the {{collection Device}} value should supercede {{collection method}}, but here the collection method should match with a value of "Composite Sampling".
A9: 256 | B9: =IF(OR(G9="NA",H9="wide_value"),"",TRUE) -> TRUE | C9: Sample collection and processing | D9: =IF(F9<>"",VLOOKUP(F9,PHA4GEVars!$A$7:$B$241,2,FALSE),"") -> Sample collection and processing | E9: PHA4GE | F9: collection device | G9: Passive (trap) sampler | H9: samples | I9: collType | J9: trap | M9: Collection device and collection method are collapsed into a single field, generally, within the ODM. So when both are being mapped to collType, the {{collection Device}} value should supercede {{collection method}}, but here the collection method should match with a value of "Passive Composite Sampling".
A10: 257 | B10: =IF(OR(G10="NA",H10="wide_value"),"",TRUE) -> TRUE | C10: Sample collection and processing | D10: =IF(F10<>"",VLOOKUP(F10,PHA4GEVars!$A$7:$B$241,2,FALSE),"") -> Sample collection and processing | E10: PHA4GE | F10: collection device | G10: Moore swab | H10: samples | I10: collType | J10: moorSw | M10: Collection device and collection method are collapsed into a single field, generally, within the ODM. So when both are being mapped to collType, the {{collection Device}} value should supercede {{collection method}}, but here the collection method should match with a value of "Passive Composite Sampling".
A11: 258 | B11: =IF(OR(G11="NA",H11="wide_value"),"",TRUE) -> TRUE | C11: Sample collection and processing | D11: =IF(F11<>"",VLOOKUP(F11,PHA4GEVars!$A$7:$B$241,2,FALSE),"") -> Sample collection and processing | E11: PHA4GE | F11: collection device | G11: Automatic composite sampler | H11: samples | I11: collType | J11: autoComp | M11: Collection device and collection method are collapsed into a single field, generally, within the ODM. So when both are being mapped to collType, the {{collection Device}} value should supercede {{collection method}}, but here the collection method should match with a value of "Automatic Composite Sampling".
A12: 259 | B12: =IF(OR(G12="NA",H12="wide_value"),"",TRUE) -> TRUE | C12: Sample collection and processing | D12: =IF(F12<>"",VLOOKUP(F12,PHA4GEVars!$A$7:$B$241,2,FALSE),"") -> Sample collection and processing | E12: PHA4GE | F12: collection device | G12: Automatic flow-proportional sampler | H12: samples | I12: collType | J12: flowPr | M12: Collection device and collection method are collapsed into a single field, generally, within the ODM. So when both are being mapped to collType, the {{collection Device}} value should supercede {{collection method}}, but here the collection method should match with a value of "Automatic Composite Sampling".
A13: 260 | B13: =IF(OR(G13="NA",H13="wide_value"),"",TRUE) -> TRUE | C13: Sample collection and processing | D13: =IF(F13<>"",VLOOKUP(F13,PHA4GEVars!$A$7:$B$241,2,FALSE),"") -> Sample collection and processing | E13: PHA4GE | F13: collection device | G13: Automatic sequential (time-proportional) sampler | H13: samples | I13: collType | J13: autoSeq | M13: Collection device and collection method are collapsed into a single field, generally, within the ODM. So when both are being mapped to collType, the {{collection Device}} value should supercede {{collection method}}, but here the collection method should match with a value of "Automatic Composite Sampling".
D14: =IF(F14<>"",VLOOKUP(F14,PHA4GEVars!$A$7:$B$241,2,FALSE),"")
A15: 261 | B15: TRUE | C15: Sample collection and processing | D15: =IF(F15<>"",VLOOKUP(F15,PHA4GEVars!$A$7:$B$241,2,FALSE),"") -> Sample collection and processing | E15: PHA4GE | F15: collection method | G15: Grab sampling | H15: samples | I15: collType | J15: grb | M15: See notes for the {{Collection Device.Grab Sampler}} entry. | N15: Need to figure out how to map both "collection device" and "collection method" to the same targetSlot=collType
A16: 262 | B16: TRUE | C16: Sample collection and processing | D16: =IF(F16<>"",VLOOKUP(F16,PHA4GEVars!$A$7:$B$241,2,FALSE),"") -> Sample collection and processing | E16: PHA4GE | F16: collection method | G16: Composite sampling | H16: samples | I16: collType | J16: comp | M16: See notes for the {{Collection Device.Composite Sampler}} entry. | N16: Need to figure out how to map both "collection device" and "collection method" to the same targetSlot=collType
